Workbook

Sheet Dashboard
W1: ▪

Sheet REGISTER SK
A1: ( Nama Perusahaan / Institusi )
A2: BUKU REGISTER SK KETUA ( Nama Perusahaan / Institusi )
A4: No. Urut | B4: Tahun | C4: Nomor SK | D4: Tgl SK | E4: TMT | F4: Perihal | G4: Cek Fisik
A5: 1
H217: 29 | I217: 2021 | J217: SK GTY untuk keperluan Dapodik
H218: 31 | I218: 2021 | J218: SK GTY untuk keperluan Dapodik
H219: 32 | I219: 2021 | J219: SK GTY untuk keperluan Dapodik
H220: 1 | I220: 2022 | J220: SK GTY untuk keperluan Dapodik
H221: 45 | I221: 2022 | J221: SK GTY untuk keperluan Dapodik
H256: x
H326: x

Sheet Draft SK
A1: Print | B1: cek | C1: x.nipy | D1: Tahun | E1: TP | F1: NO.DP | G1: Jenis | H1: Nama | I1: Nomor | J1: Bulan Laporan | K1: Nomor Laporan Penilaian | L1: TGL SKP | M1: TMT | N1: NIPY | O1: TTL | P1: Pendidikan | Q1: Tugas | R1: SK P/G TT PERTAMA | S1: TMT Pertama Kali | T1: MK Lama | U1: MK Baru | V1: Detail | W1: NAMA SK | Y1: H.M.Kerja | Z1: Tahun | AA1: Bulan | AB1: Last ptt/gtt | AC1: Bantu SK | AD1: Hitung BSK | AE1: GTT/GTY | AF1: No.SK | AG1: Tgl SK | AH1: TMT | AI1: Tanggal SK | AJ1: tgl | AK1: bulan | AL1: Tahun | AM1: Pertama TT | AN1: tgl | AO1: bulan | AP1: Tahun | AQ1: TMT ini | AR1: tgl | AS1: bulan | AT1: Tahun | AU1: LAPORAN PENILAIAN
A2: 1 | B2: ok | C2: =IF(G2="","",IF(G2="Umum",G2,VLOOKUP(F2,'Data Induk Pegawai'!B:AE,4,FALSE))) | D2: =IF('REGISTER SK'!A5="","",IF('REGISTER SK'!B5=0,D1,'REGISTER SK'!B5)) -> Tahun | E2: 2015/2016 | H2: =IF(F2="","",VLOOKUP(F2,'Data Induk Pegawai'!B:U,2,FALSE)) | I2: =IF('REGISTER SK'!C5="","",'REGISTER SK'!C5) | L2: =IF('REGISTER SK'!D5="","",'REGISTER SK'!D5) | M2: =IF('REGISTER SK'!E5="","",'REGISTER SK'!E5) | N2: =IF(G2="","",IF(OR(G2="GTT",G2="PTT"),"--",VLOOKUP(F2,'Data Induk Pegawai'!B:AE,4,FALSE))) | O2: Pemalang, 17 Mei 1979 | P2: =IF(G2="","",VLOOKUP(F2,'Data Induk Pegawai'!B:AE,7,FALSE)) | R2: =IF(G2="","","Nomor "&RIGHT(VLOOKUP(F2,'Data Induk Pegawai'!B:AE,12,FALSE),2)&" Tahun "&MID(VLOOKUP(F2,'Data Induk Pegawai'!B:AE,12,FALSE),5,4)) | S2: =IF(G2="","",VLOOKUP(F2,'Data Induk Pegawai'!B:AE,11,FALSE)) | U2: =IF(Y2="","",IF(Z2<1,AA2&" Bulan",IF(AND(Z2>0,AA2=0),Z2&" Tahun",Z2&" Tahun "&AA2&" Bulan"))) | W2: =V2&H2 | Y2: =IFERROR(IF(S2="","",DATEDIF(S2,M2,"M")),"?") | Z2: =IFERROR(IF(Y2="","",ROUNDDOWN(Y2/12,0)),"-") | AA2: =IFERROR(IF(Y2="","",Y2-Z2*12),"-") | AB2: =COUNTIFS(AC2:AC$596,AC2)&AC2 -> 595 | AC2: =IF(LEFT(V2,16)="SK Pemberhentian","OUT"&F2,IF(RIGHT(G2,2)="TT","GPTT",IF(RIGHT(G2,2)="TY","GPTY",G2))&F2) | AD2: =COUNTIFS(AC$2:AC2,AC2)&AC2 -> 1 | AE2: =IF(LEFT(V2,16)="SK Pemberhentian",E2&"OUT"&F2,E2&G2&F2) -> 2015/2016 | AF2: =G2&"."&D2&"."&I2 -> .Tahun. | AG2: =L2 | AH2: =M2 | AI2: =IF(AG2="","",AJ2&" "&VLOOKUP(AK2,AX:AY,2,FALSE)&" "&AL2) | AJ2: =TEXT(AG2,"D") | AK2: =TEXT(AG2,"MMMM") | AL2: =TEXT(AG2,"YYYY") | AM2: =IF(AI2="","",AN2&" "&VLOOKUP(AO2,AX:AY,2,FALSE)&" "&AP2) | AN2: =TEXT(S2,"D") | AO2: =TEXT(S2,"MMMM") | AP2: =TEXT(S2,"YYYY") | AQ2: =IF(AM2="","",AR2&" "&VLOOKUP(AS2,AX:AY,2,FALSE)&" "&AT2) | AR2: =TEXT(M2,"D") | AS2: =TEXT(M2,"MMMM") | AT2: =TEXT(M2,"YYYY") | AU2: =IF(OR(G2="Umum",G2=""),"",VLOOKUP(VALUE(TEXT(M2,"M")-1),AW:AY,3,FALSE)) | AW2: 1 | AX2: January | AY2: Januari | BA2: ='REGISTER SK'!F5 -> 0
A3: 2 | B3: ok | C3: =IF(G3="","",IF(G3="Umum",G3,VLOOKUP(F3,'Data Induk Pegawai'!B:AE,4,FALSE))) | D3: =IF('REGISTER SK'!A6="","",IF('REGISTER SK'!B6=0,D2,'REGISTER SK'!B6)) | E3: =IF(D3="","",D3&"/"&D3+1) | H3: =IF(F3="","",VLOOKUP(F3,'Data Induk Pegawai'!B:U,2,FALSE)) | I3: =IF('REGISTER SK'!C6="","",'REGISTER SK'!C6) | L3: =IF('REGISTER SK'!D6="","",'REGISTER SK'!D6) | M3: =IF('REGISTER SK'!E6="","",'REGISTER SK'!E6) | N3: =IF(G3="","",IF(OR(G3="GTT",G3="PTT"),"--",VLOOKUP(F3,'Data Induk Pegawai'!B:AE,4,FALSE))) | O3: Pemalang, 27 Februari 1990 | P3: =IF(G3="","",VLOOKUP(F3,'Data Induk Pegawai'!B:AE,7,FALSE)) | R3: =IF(G3="","","Nomor "&RIGHT(VLOOKUP(F3,'Data Induk Pegawai'!B:AE,12,FALSE),2)&" Tahun "&MID(VLOOKUP(F3,'Data Induk Pegawai'!B:AE,12,FALSE),5,4)) | S3: =IF(G3="","",VLOOKUP(F3,'Data Induk Pegawai'!B:AE,11,FALSE)) | U3: =IF(Y3="","",IF(Z3<1,AA3&" Bulan",IF(AND(Z3>0,AA3=0),Z3&" Tahun",Z3&" Tahun "&AA3&" Bulan"))) | W3: =V3&H3 | Y3: =IFERROR(IF(S3="","",DATEDIF(S3,M3,"M")),"?") | Z3: =IFERROR(IF(Y3="","",ROUNDDOWN(Y3/12,0)),"-") | AA3: =IFERROR(IF(Y3="","",Y3-Z3*12),"-") | AB3: =COUNTIFS(AC3:AC$596,AC3)&AC3 -> 594 | AC3: =IF(LEFT(V3,16)="SK Pemberhentian","OUT"&F3,IF(RIGHT(G3,2)="TT","GPTT",IF(RIGHT(G3,2)="TY","GPTY",G3))&F3) | AD3: =COUNTIFS(AC$2:AC3,AC3)&AC3 -> 2 | AE3: =IF(LEFT(V3,16)="SK Pemberhentian",E3&"OUT"&F3,E3&G3&F3) | AF3: =G3&"."&D3&"."&I3 -> .. | AG3: =L3 | AH3: =M3 | AI3: =IF(AG3="","",AJ3&" "&VLOOKUP(AK3,AX:AY,2,FALSE)&" "&AL3) | AJ3: =TEXT(AG3,"D") | AK3: =TEXT(AG3,"MMMM") | AL3: =TEXT(AG3,"YYYY") | AM3: =IF(AI3="","",AN3&" "&VLOOKUP(AO3,AX:AY,2,FALSE)&" "&AP3) | AN3: =TEXT(S3,"D") | AO3: =TEXT(S3,"MMMM") | AP3: =TEXT(S3,"YYYY") | AQ3: =IF(AM3="","",AR3&" "&VLOOKUP(AS3,AX:AY,2,FALSE)&" "&AT3) | AR3: =TEXT(M3,"D") | AS3: =TEXT(M3,"MMMM") | AT3: =TEXT(M3,"YYYY") | AU3: =IF(OR(G3="Umum",G3=""),"",VLOOKUP(VALUE(TEXT(M3,"M")-1),AW:AY,3,FALSE)) | AW3: 2 | AX3: February | AY3: Februari | BA3: ='REGISTER SK'!F6 -> 0
A4: 3 | B4: ok | C4: =IF(G4="","",IF(G4="Umum",G4,VLOOKUP(F4,'Data Induk Pegawai'!B:AE,4,FALSE))) | D4: =IF('REGISTER SK'!A7="","",IF('REGISTER SK'!B7=0,D3,'REGISTER SK'!B7)) | E4: =IF(D4="","",D4&"/"&D4+1) | H4: =IF(F4="","",VLOOKUP(F4,'Data Induk Pegawai'!B:U,2,FALSE)) | I4: =IF('REGISTER SK'!C7="","",'REGISTER SK'!C7) | L4: =IF('REGISTER SK'!D7="","",'REGISTER SK'!D7) | M4: =IF('REGISTER SK'!E7="","",'REGISTER SK'!E7) | N4: =IF(G4="","",IF(OR(G4="GTT",G4="PTT"),"--",VLOOKUP(F4,'Data Induk Pegawai'!B:AE,4,FALSE))) | O4: Pemalang, 24 April 1996 | P4: =IF(G4="","",VLOOKUP(F4,'Data Induk Pegawai'!B:AE,7,FALSE)) | R4: =IF(G4="","","Nomor "&RIGHT(VLOOKUP(F4,'Data Induk Pegawai'!B:AE,12,FALSE),2)&" Tahun "&MID(VLOOKUP(F4,'Data Induk Pegawai'!B:AE,12,FALSE),5,4)) | S4: =IF(G4="","",VLOOKUP(F4,'Data Induk Pegawai'!B:AE,11,FALSE)) | U4: =IF(Y4="","",IF(Z4<1,AA4&" Bulan",IF(AND(Z4>0,AA4=0),Z4&" Tahun",Z4&" Tahun "&AA4&" Bulan"))) | W4: =V4&H4 | Y4: =IFERROR(IF(S4="","",DATEDIF(S4,M4,"M")),"?") | Z4: =IFERROR(IF(Y4="","",ROUNDDOWN(Y4/12,0)),"-") | AA4: =IFERROR(IF(Y4="","",Y4-Z4*12),"-") | AB4: =COUNTIFS(AC4:AC$596,AC4)&AC4 -> 593 | AC4: =IF(LEFT(V4,16)="SK Pemberhentian","OUT"&F4,IF(RIGHT(G4,2)="TT","GPTT",IF(RIGHT(G4,2)="TY","GPTY",G4))&F4) | AD4: =COUNTIFS(AC$2:AC4,AC4)&AC4 -> 3 | AE4: =IF(LEFT(V4,16)="SK Pemberhentian",E4&"OUT"&F4,E4&G4&F4) | AF4: =G4&"."&D4&"."&I4 -> .. | AG4: =L4 | AH4: =M4 | AI4: =IF(AG4="","",AJ4&" "&VLOOKUP(AK4,AX:AY,2,FALSE)&" "&AL4) | AJ4: =TEXT(AG4,"D") | AK4: =TEXT(AG4,"MMMM") | AL4: =TEXT(AG4,"YYYY") | AM4: =IF(AI4="","",AN4&" "&VLOOKUP(AO4,AX:AY,2,FALSE)&" "&AP4) | AN4: =TEXT(S4,"D") | AO4: =TEXT(S4,"MMMM") | AP4: =TEXT(S4,"YYYY") | AQ4: =IF(AM4="","",AR4&" "&VLOOKUP(AS4,AX:AY,2,FALSE)&" "&AT4) | AR4: =TEXT(M4,"D") | AS4: =TEXT(M4,"MMMM") | AT4: =TEXT(M4,"YYYY") | AU4: =IF(OR(G4="Umum",G4=""),"",VLOOKUP(VALUE(TEXT(M4,"M")-1),AW:AY,3,FALSE)) | AW4: 3 | AX4: March | AY4: Maret | BA4: ='REGISTER SK'!F7 -> 0
A5: 4 | B5: ok | C5: =IF(G5="","",IF(G5="Umum",G5,VLOOKUP(F5,'Data Induk Pegawai'!B:AE,4,FALSE))) | D5: =IF('REGISTER SK'!A8="","",IF('REGISTER SK'!B8=0,D4,'REGISTER SK'!B8)) | E5: =IF(D5="","",D5&"/"&D5+1) | H5: =IF(F5="","",VLOOKUP(F5,'Data Induk Pegawai'!B:U,2,FALSE)) | I5: =IF('REGISTER SK'!C8="","",'REGISTER SK'!C8) | L5: =IF('REGISTER SK'!D8="","",'REGISTER SK'!D8) | M5: =IF('REGISTER SK'!E8="","",'REGISTER SK'!E8) | N5: =IF(G5="","",IF(OR(G5="GTT",G5="PTT"),"--",VLOOKUP(F5,'Data Induk Pegawai'!B:AE,4,FALSE))) | O5: Pemalang, 15 Agustus 1996 | P5: =IF(G5="","",VLOOKUP(F5,'Data Induk Pegawai'!B:AE,7,FALSE)) | R5: =IF(G5="","","Nomor "&RIGHT(VLOOKUP(F5,'Data Induk Pegawai'!B:AE,12,FALSE),2)&" Tahun "&MID(VLOOKUP(F5,'Data Induk Pegawai'!B:AE,12,FALSE),5,4)) | S5: =IF(G5="","",VLOOKUP(F5,'Data Induk Pegawai'!B:AE,11,FALSE)) | U5: =IF(Y5="","",IF(Z5<1,AA5&" Bulan",IF(AND(Z5>0,AA5=0),Z5&" Tahun",Z5&" Tahun "&AA5&" Bulan"))) | W5: =V5&H5 | Y5: =IFERROR(IF(S5="","",DATEDIF(S5,M5,"M")),"?") | Z5: =IFERROR(IF(Y5="","",ROUNDDOWN(Y5/12,0)),"-") | AA5: =IFERROR(IF(Y5="","",Y5-Z5*12),"-") | AB5: =COUNTIFS(AC5:AC$596,AC5)&AC5 -> 592 | AC5: =IF(LEFT(V5,16)="SK Pemberhentian","OUT"&F5,IF(RIGHT(G5,2)="TT","GPTT",IF(RIGHT(G5,2)="TY","GPTY",G5))&F5) | AD5: =COUNTIFS(AC$2:AC5,AC5)&AC5 -> 4 | AE5: =IF(LEFT(V5,16)="SK Pemberhentian",E5&"OUT"&F5,E5&G5&F5) | AF5: =G5&"."&D5&"."&I5 -> .. | AG5: =L5 | AH5: =M5 | AI5: =IF(AG5="","",AJ5&" "&VLOOKUP(AK5,AX:AY,2,FALSE)&" "&AL5) | AJ5: =TEXT(AG5,"D") | AK5: =TEXT(AG5,"MMMM") | AL5: =TEXT(AG5,"YYYY") | AM5: =IF(AI5="","",AN5&" "&VLOOKUP(AO5,AX:AY,2,FALSE)&" "&AP5) | AN5: =TEXT(S5,"D") | AO5: =TEXT(S5,"MMMM") | AP5: =TEXT(S5,"YYYY") | AQ5: =IF(AM5="","",AR5&" "&VLOOKUP(AS5,AX:AY,2,FALSE)&" "&AT5) | AR5: =TEXT(M5,"D") | AS5: =TEXT(M5,"MMMM") | AT5: =TEXT(M5,"YYYY") | AU5: =IF(OR(G5="Umum",G5=""),"",VLOOKUP(VALUE(TEXT(M5,"M")-1),AW:AY,3,FALSE)) | AW5: 4 | AX5: April | AY5: April | BA5: ='REGISTER SK'!F8 -> 0
A6: 5 | B6: ok | C6: =IF(G6="","",IF(G6="Umum",G6,VLOOKUP(F6,'Data Induk Pegawai'!B:AE,4,FALSE))) | D6: =IF('REGISTER SK'!A9="","",IF('REGISTER SK'!B9=0,D5,'REGISTER SK'!B9)) | E6: =IF(D6="","",D6&"/"&D6+1) | H6: =IF(F6="","",VLOOKUP(F6,'Data Induk Pegawai'!B:U,2,FALSE)) | I6: =IF('REGISTER SK'!C9="","",'REGISTER SK'!C9) | L6: =IF('REGISTER SK'!D9="","",'REGISTER SK'!D9) | M6: =IF('REGISTER SK'!E9="","",'REGISTER SK'!E9) | N6: =IF(G6="","",IF(OR(G6="GTT",G6="PTT"),"--",VLOOKUP(F6,'Data Induk Pegawai'!B:AE,4,FALSE))) | O6: Pemalang, 17 Mei 1979 | P6: =IF(G6="","",VLOOKUP(F6,'Data Induk Pegawai'!B:AE,7,FALSE)) | R6: =IF(G6="","","Nomor "&RIGHT(VLOOKUP(F6,'Data Induk Pegawai'!B:AE,12,FALSE),2)&" Tahun "&MID(VLOOKUP(F6,'Data Induk Pegawai'!B:AE,12,FALSE),5,4)) | S6: =IF(G6="","",VLOOKUP(F6,'Data Induk Pegawai'!B:AE,11,FALSE)) | U6: =IF(Y6="","",IF(Z6<1,AA6&" Bulan",IF(AND(Z6>0,AA6=0),Z6&" Tahun",Z6&" Tahun "&AA6&" Bulan"))) | W6: =V6&H6 | Y6: =IFERROR(IF(S6="","",DATEDIF(S6,M6,"M")),"?") | Z6: =IFERROR(IF(Y6="","",ROUNDDOWN(Y6/12,0)),"-") | AA6: =IFERROR(IF(Y6="","",Y6-Z6*12),"-") | AB6: =COUNTIFS(AC6:AC$596,AC6)&AC6 -> 591 | AC6: =IF(LEFT(V6,16)="SK Pemberhentian","OUT"&F6,IF(RIGHT(G6,2)="TT","GPTT",IF(RIGHT(G6,2)="TY","GPTY",G6))&F6) | AD6: =COUNTIFS(AC$2:AC6,AC6)&AC6 -> 5 | AE6: =IF(LEFT(V6,16)="SK Pemberhentian",E6&"OUT"&F6,E6&G6&F6) | AF6: =G6&"."&D6&"."&I6 -> .. | AG6: =L6 | AH6: =M6 | AI6: =IF(AG6="","",AJ6&" "&VLOOKUP(AK6,AX:AY,2,FALSE)&" "&AL6) | AJ6: =TEXT(AG6,"D") | AK6: =TEXT(AG6,"MMMM") | AL6: =TEXT(AG6,"YYYY") | AM6: =IF(AI6="","",AN6&" "&VLOOKUP(AO6,AX:AY,2,FALSE)&" "&AP6) | AN6: =TEXT(S6,"D") | AO6: =TEXT(S6,"MMMM") | AP6: =TEXT(S6,"YYYY") | AQ6: =IF(AM6="","",AR6&" "&VLOOKUP(AS6,AX:AY,2,FALSE)&" "&AT6) | AR6: =TEXT(M6,"D") | AS6: =TEXT(M6,"MMMM") | AT6: =TEXT(M6,"YYYY") | AU6: =IF(OR(G6="Umum",G6=""),"",VLOOKUP(VALUE(TEXT(M6,"M")-1),AW:AY,3,FALSE)) | AW6: 5 | AX6: May | AY6: Mei | BA6: ='REGISTER SK'!F9 -> 0
A7: 6 | B7: ok | C7: =IF(G7="","",IF(G7="Umum",G7,VLOOKUP(F7,'Data Induk Pegawai'!B:AE,4,FALSE))) | D7: =IF('REGISTER SK'!A10="","",IF('REGISTER SK'!B10=0,D6,'REGISTER SK'!B10)) | E7: =IF(D7="","",D7&"/"&D7+1) | H7: =IF(F7="","",VLOOKUP(F7,'Data Induk Pegawai'!B:U,2,FALSE)) | I7: =IF('REGISTER SK'!C10="","",'REGISTER SK'!C10) | L7: =IF('REGISTER SK'!D10="","",'REGISTER SK'!D10) | M7: =IF('REGISTER SK'!E10="","",'REGISTER SK'!E10) | N7: =IF(G7="","",IF(OR(G7="GTT",G7="PTT"),"--",VLOOKUP(F7,'Data Induk Pegawai'!B:AE,4,FALSE))) | O7: Pemalang, 25 Desember 1986 | P7: =IF(G7="","",VLOOKUP(F7,'Data Induk Pegawai'!B:AE,7,FALSE)) | R7: =IF(G7="","","Nomor "&RIGHT(VLOOKUP(F7,'Data Induk Pegawai'!B:AE,12,FALSE),2)&" Tahun "&MID(VLOOKUP(F7,'Data Induk Pegawai'!B:AE,12,FALSE),5,4)) | S7: =IF(G7="","",VLOOKUP(F7,'Data Induk Pegawai'!B:AE,11,FALSE)) | U7: =IF(Y7="","",IF(Z7<1,AA7&" Bulan",IF(AND(Z7>0,AA7=0),Z7&" Tahun",Z7&" Tahun "&AA7&" Bulan"))) | W7: =V7&H7 | Y7: =IFERROR(IF(S7="","",DATEDIF(S7,M7,"M")),"?") | Z7: =IFERROR(IF(Y7="","",ROUNDDOWN(Y7/12,0)),"-") | AA7: =IFERROR(IF(Y7="","",Y7-Z7*12),"-") | AB7: =COUNTIFS(AC7:AC$596,AC7)&AC7 -> 590 | AC7: =IF(LEFT(V7,16)="SK Pemberhentian","OUT"&F7,IF(RIGHT(G7,2)="TT","GPTT",IF(RIGHT(G7,2)="TY","GPTY",G7))&F7) | AD7: =COUNTIFS(AC$2:AC7,AC7)&AC7 -> 6 | AE7: =IF(LEFT(V7,16)="SK Pemberhentian",E7&"OUT"&F7,E7&G7&F7) | AF7: =G7&"."&D7&"."&I7 -> .. | AG7: =L7 | AH7: =M7 | AI7: =IF(AG7="","",AJ7&" "&VLOOKUP(AK7,AX:AY,2,FALSE)&" "&AL7) | AJ7: =TEXT(AG7,"D") | AK7: =TEXT(AG7,"MMMM") | AL7: =TEXT(AG7,"YYYY") | AM7: =IF(AI7="","",AN7&" "&VLOOKUP(AO7,AX:AY,2,FALSE)&" "&AP7) | AN7: =TEXT(S7,"D") | AO7: =TEXT(S7,"MMMM") | AP7: =TEXT(S7,"YYYY") | AQ7: =IF(AM7="","",AR7&" "&VLOOKUP(AS7,AX:AY,2,FALSE)&" "&AT7) | AR7: =TEXT(M7,"D") | AS7: =TEXT(M7,"MMMM") | AT7: =TEXT(M7,"YYYY") | AU7: =IF(OR(G7="Umum",G7=""),"",VLOOKUP(VALUE(TEXT(M7,"M")-1),AW:AY,3,FALSE)) | AW7: 6 | AX7: June | AY7: Juni | BA7: ='REGISTER SK'!F10 -> 0
A8: 7 | B8: ok | C8: =IF(G8="","",IF(G8="Umum",G8,VLOOKUP(F8,'Data Induk Pegawai'!B:AE,4,FALSE))) | D8: =IF('REGISTER SK'!A11="","",IF('REGISTER SK'!B11=0,D7,'REGISTER SK'!B11)) | E8: =IF(D8="","",D8&"/"&D8+1) | H8: =IF(F8="","",VLOOKUP(F8,'Data Induk Pegawai'!B:U,2,FALSE)) | I8: =IF('REGISTER SK'!C11="","",'REGISTER SK'!C11) | L8: =IF('REGISTER SK'!D11="","",'REGISTER SK'!D11) | M8: =IF('REGISTER SK'!E11="","",'REGISTER SK'!E11) | N8: =IF(G8="","",IF(OR(G8="GTT",G8="PTT"),"--",VLOOKUP(F8,'Data Induk Pegawai'!B:AE,4,FALSE))) | O8: Pemalang, 20 Februari 1981 | P8: =IF(G8="","",VLOOKUP(F8,'Data Induk Pegawai'!B:AE,7,FALSE)) | R8: =IF(G8="","","Nomor "&RIGHT(VLOOKUP(F8,'Data Induk Pegawai'!B:AE,12,FALSE),2)&" Tahun "&MID(VLOOKUP(F8,'Data Induk Pegawai'!B:AE,12,FALSE),5,4)) | S8: =IF(G8="","",VLOOKUP(F8,'Data Induk Pegawai'!B:AE,11,FALSE)) | U8: =IF(Y8="","",IF(Z8<1,AA8&" Bulan",IF(AND(Z8>0,AA8=0),Z8&" Tahun",Z8&" Tahun "&AA8&" Bulan"))) | W8: =V8&H8 | Y8: =IFERROR(IF(S8="","",DATEDIF(S8,M8,"M")),"?") | Z8: =IFERROR(IF(Y8="","",ROUNDDOWN(Y8/12,0)),"-") | AA8: =IFERROR(IF(Y8="","",Y8-Z8*12),"-") | AB8: =COUNTIFS(AC8:AC$596,AC8)&AC8 -> 589 | AC8: =IF(LEFT(V8,16)="SK Pemberhentian","OUT"&F8,IF(RIGHT(G8,2)="TT","GPTT",IF(RIGHT(G8,2)="TY","GPTY",G8))&F8) | AD8: =COUNTIFS(AC$2:AC8,AC8)&AC8 -> 7 | AE8: =IF(LEFT(V8,16)="SK Pemberhentian",E8&"OUT"&F8,E8&G8&F8) | AF8: =G8&"."&D8&"."&I8 -> .. | AG8: =L8 | AH8: =M8 | AI8: =IF(AG8="","",AJ8&" "&VLOOKUP(AK8,AX:AY,2,FALSE)&" "&AL8) | AJ8: =TEXT(AG8,"D") | AK8: =TEXT(AG8,"MMMM") | AL8: =TEXT(AG8,"YYYY") | AM8: =IF(AI8="","",AN8&" "&VLOOKUP(AO8,AX:AY,2,FALSE)&" "&AP8) | AN8: =TEXT(S8,"D") | AO8: =TEXT(S8,"MMMM") | AP8: =TEXT(S8,"YYYY") | AQ8: =IF(AM8="","",AR8&" "&VLOOKUP(AS8,AX:AY,2,FALSE)&" "&AT8) | AR8: =TEXT(M8,"D") | AS8: =TEXT(M8,"MMMM") | AT8: =TEXT(M8,"YYYY") | AU8: =IF(OR(G8="Umum",G8=""),"",VLOOKUP(VALUE(TEXT(M8,"M")-1),AW:AY,3,FALSE)) | AW8: 7 | AX8: July | AY8: Juli | BA8: ='REGISTER SK'!F11 -> 0
A9: 8 | B9: ok | C9: =IF(G9="","",IF(G9="Umum",G9,VLOOKUP(F9,'Data Induk Pegawai'!B:AE,4,FALSE))) | D9: =IF('REGISTER SK'!A12="","",IF('REGISTER SK'!B12=0,D8,'REGISTER SK'!B12)) | E9: =IF(D9="","",D9&"/"&D9+1) | H9: =IF(F9="","",VLOOKUP(F9,'Data Induk Pegawai'!B:U,2,FALSE)) | I9: =IF('REGISTER SK'!C12="","",'REGISTER SK'!C12) | L9: =IF('REGISTER SK'!D12="","",'REGISTER SK'!D12) | M9: =IF('REGISTER SK'!E12="","",'REGISTER SK'!E12) | N9: =IF(G9="","",IF(OR(G9="GTT",G9="PTT"),"--",VLOOKUP(F9,'Data Induk Pegawai'!B:AE,4,FALSE))) | O9: Pemalang, 20 Februari 1981 | P9: =IF(G9="","",VLOOKUP(F9,'Data Induk Pegawai'!B:AE,7,FALSE)) | R9: =IF(G9="","","Nomor "&RIGHT(VLOOKUP(F9,'Data Induk Pegawai'!B:AE,12,FALSE),2)&" Tahun "&MID(VLOOKUP(F9,'Data Induk Pegawai'!B:AE,12,FALSE),5,4)) | S9: =IF(G9="","",VLOOKUP(F9,'Data Induk Pegawai'!B:AE,11,FALSE)) | U9: =IF(Y9="","",IF(Z9<1,AA9&" Bulan",IF(AND(Z9>0,AA9=0),Z9&" Tahun",Z9&" Tahun "&AA9&" Bulan"))) | W9: =V9&H9 | Y9: =IFERROR(IF(S9="","",DATEDIF(S9,M9,"M")),"?") | Z9: =IFERROR(IF(Y9="","",ROUNDDOWN(Y9/12,0)),"-") | AA9: =IFERROR(IF(Y9="","",Y9-Z9*12),"-") | AB9: =COUNTIFS(AC9:AC$596,AC9)&AC9 -> 588 | AC9: =IF(LEFT(V9,16)="SK Pemberhentian","OUT"&F9,IF(RIGHT(G9,2)="TT","GPTT",IF(RIGHT(G9,2)="TY","GPTY",G9))&F9) | AD9: =COUNTIFS(AC$2:AC9,AC9)&AC9 -> 8 | AE9: =IF(LEFT(V9,16)="SK Pemberhentian",E9&"OUT"&F9,E9&G9&F9) | AF9: =G9&"."&D9&"."&I9 -> .. | AG9: =L9 | AH9: =M9 | AI9: =IF(AG9="","",AJ9&" "&VLOOKUP(AK9,AX:AY,2,FALSE)&" "&AL9) | AJ9: =TEXT(AG9,"D") | AK9: =TEXT(AG9,"MMMM") | AL9: =TEXT(AG9,"YYYY") | AM9: =IF(AI9="","",AN9&" "&VLOOKUP(AO9,AX:AY,2,FALSE)&" "&AP9) | AN9: =TEXT(S9,"D") | AO9: =TEXT(S9,"MMMM") | AP9: =TEXT(S9,"YYYY") | AQ9: =IF(AM9="","",AR9&" "&VLOOKUP(AS9,AX:AY,2,FALSE)&" "&AT9) | AR9: =TEXT(M9,"D") | AS9: =TEXT(M9,"MMMM") | AT9: =TEXT(M9,"YYYY") | AU9: =IF(OR(G9="Umum",G9=""),"",VLOOKUP(VALUE(TEXT(M9,"M")-1),AW:AY,3,FALSE)) | AW9: 8 | AX9: August | AY9: Agustus | BA9: ='REGISTER SK'!F12 -> 0
A10: 9 | C10: =IF(G10="","",IF(G10="Umum",G10,VLOOKUP(F10,'Data Induk Pegawai'!B:AE,4,FALSE))) | D10: =IF('REGISTER SK'!A13="","",IF('REGISTER SK'!B13=0,D9,'REGISTER SK'!B13)) | E10: =IF(D10="","",D10&"/"&D10+1) | H10: =IF(F10="","",VLOOKUP(F10,'Data Induk Pegawai'!B:U,2,FALSE)) | I10: =IF('REGISTER SK'!C13="","",'REGISTER SK'!C13) | L10: =IF('REGISTER SK'!D13="","",'REGISTER SK'!D13) | M10: =IF('REGISTER SK'!E13="","",'REGISTER SK'!E13) | N10: =IF(G10="","",IF(OR(G10="GTT",G10="PTT"),"--",VLOOKUP(F10,'Data Induk Pegawai'!B:AE,4,FALSE))) | P10: =IF(G10="","",VLOOKUP(F10,'Data Induk Pegawai'!B:AE,7,FALSE)) | R10: =IF(G10="","","Nomor "&RIGHT(VLOOKUP(F10,'Data Induk Pegawai'!B:AE,12,FALSE),2)&" Tahun "&MID(VLOOKUP(F10,'Data Induk Pegawai'!B:AE,12,FALSE),5,4)) | S10: =IF(G10="","",VLOOKUP(F10,'Data Induk Pegawai'!B:AE,11,FALSE)) | U10: =IF(Y10="","",IF(Z10<1,AA10&" Bulan",IF(AND(Z10>0,AA10=0),Z10&" Tahun",Z10&" Tahun "&AA10&" Bulan"))) | W10: =V10&H10 | Y10: =IFERROR(IF(S10="","",DATEDIF(S10,M10,"M")),"?") | Z10: =IFERROR(IF(Y10="","",ROUNDDOWN(Y10/12,0)),"-") | AA10: =IFERROR(IF(Y10="","",Y10-Z10*12),"-") | AB10: =COUNTIFS(AC10:AC$596,AC10)&AC10 -> 587 | AC10: =IF(LEFT(V10,16)="SK Pemberhentian","OUT"&F10,IF(RIGHT(G10,2)="TT","GPTT",IF(RIGHT(G10,2)="TY","GPTY",G10))&F10) | AD10: =COUNTIFS(AC$2:AC10,AC10)&AC10 -> 9 | AE10: =IF(LEFT(V10,16)="SK Pemberhentian",E10&"OUT"&F10,E10&G10&F10) | AF10: =G10&"."&D10&"."&I10 -> .. | AG10: =L10 | AH10: =M10 | AI10: =IF(AG10="","",AJ10&" "&VLOOKUP(AK10,AX:AY,2,FALSE)&" "&AL10) | AJ10: =TEXT(AG10,"D") | AK10: =TEXT(AG10,"MMMM") | AL10: =TEXT(AG10,"YYYY") | AM10: =IF(AI10="","",AN10&" "&VLOOKUP(AO10,AX:AY,2,FALSE)&" "&AP10) | AN10: =TEXT(S10,"D") | AO10: =TEXT(S10,"MMMM") | AP10: =TEXT(S10,"YYYY") | AQ10: =IF(AM10="","",AR10&" "&VLOOKUP(AS10,AX:AY,2,FALSE)&" "&AT10) | AR10: =TEXT(M10,"D") | AS10: =TEXT(M10,"MMMM") | AT10: =TEXT(M10,"YYYY") | AU10: =IF(OR(G10="Umum",G10=""),"",VLOOKUP(VALUE(TEXT(M10,"M")-1),AW:AY,3,FALSE)) | AW10: 9 | AX10: September | AY10: September | BA10: ='REGISTER SK'!F13 -> 0
A11: 10 | B11: ok | C11: =IF(G11="","",IF(G11="Umum",G11,VLOOKUP(F11,'Data Induk Pegawai'!B:AE,4,FALSE))) | D11: =IF('REGISTER SK'!A14="","",IF('REGISTER SK'!B14=0,D10,'REGISTER SK'!B14)) | E11: =IF(D11="","",D11&"/"&D11+1) | H11: =IF(F11="","",VLOOKUP(F11,'Data Induk Pegawai'!B:U,2,FALSE)) | I11: =IF('REGISTER SK'!C14="","",'REGISTER SK'!C14) | L11: =IF('REGISTER SK'!D14="","",'REGISTER SK'!D14) | M11: =IF('REGISTER SK'!E14="","",'REGISTER SK'!E14) | N11: =IF(G11="","",IF(OR(G11="GTT",G11="PTT"),"--",VLOOKUP(F11,'Data Induk Pegawai'!B:AE,4,FALSE))) | O11: Pemalang, 17 Mei 1979 | P11: =IF(G11="","",VLOOKUP(F11,'Data Induk Pegawai'!B:AE,7,FALSE)) | R11: =IF(G11="","","Nomor "&RIGHT(VLOOKUP(F11,'Data Induk Pegawai'!B:AE,12,FALSE),2)&" Tahun "&MID(VLOOKUP(F11,'Data Induk Pegawai'!B:AE,12,FALSE),5,4)) | S11: =IF(G11="","",VLOOKUP(F11,'Data Induk Pegawai'!B:AE,11,FALSE)) | U11: =IF(Y11="","",IF(Z11<1,AA11&" Bulan",IF(AND(Z11>0,AA11=0),Z11&" Tahun",Z11&" Tahun "&AA11&" Bulan"))) | W11: =V11&H11 | Y11: =IFERROR(IF(S11="","",DATEDIF(S11,M11,"M")),"?") | Z11: =IFERROR(IF(Y11="","",ROUNDDOWN(Y11/12,0)),"-") | AA11: =IFERROR(IF(Y11="","",Y11-Z11*12),"-") | AB11: =COUNTIFS(AC11:AC$596,AC11)&AC11 -> 586 | AC11: =IF(LEFT(V11,16)="SK Pemberhentian","OUT"&F11,IF(RIGHT(G11,2)="TT","GPTT",IF(RIGHT(G11,2)="TY","GPTY",G11))&F11) | AD11: =COUNTIFS(AC$2:AC11,AC11)&AC11 -> 10 | AE11: =IF(LEFT(V11,16)="SK Pemberhentian",E11&"OUT"&F11,E11&G11&F11) | AF11: =G11&"."&D11&"."&I11 -> .. | AG11: =L11 | AH11: =M11 | AI11: =IF(AG11="","",AJ11&" "&VLOOKUP(AK11,AX:AY,2,FALSE)&" "&AL11) | AJ11: =TEXT(AG11,"D") | AK11: =TEXT(AG11,"MMMM") | AL11: =TEXT(AG11,"YYYY") | AM11: =IF(AI11="","",AN11&" "&VLOOKUP(AO11,AX:AY,2,FALSE)&" "&AP11) | AN11: =TEXT(S11,"D") | AO11: =TEXT(S11,"MMMM") | AP11: =TEXT(S11,"YYYY") | AQ11: =IF(AM11="","",AR11&" "&VLOOKUP(AS11,AX:AY,2,FALSE)&" "&AT11) | AR11: =TEXT(M11,"D") | AS11: =TEXT(M11,"MMMM") | AT11: =TEXT(M11,"YYYY") | AU11: =IF(OR(G11="Umum",G11=""),"",VLOOKUP(VALUE(TEXT(M11,"M")-1),AW:AY,3,FALSE)) | AW11: 10 | AX11: October | AY11: Oktober | BA11: ='REGISTER SK'!F14 -> 0
A12: 11 | B12: ok | C12: =IF(G12="","",IF(G12="Umum",G12,VLOOKUP(F12,'Data Induk Pegawai'!B:AE,4,FALSE))) | D12: =IF('REGISTER SK'!A15="","",IF('REGISTER SK'!B15=0,D11,'REGISTER SK'!B15)) | E12: =IF(D12="","",D12&"/"&D12+1) | H12: =IF(F12="","",VLOOKUP(F12,'Data Induk Pegawai'!B:U,2,FALSE)) | I12: =IF('REGISTER SK'!C15="","",'REGISTER SK'!C15) | L12: =IF('REGISTER SK'!D15="","",'REGISTER SK'!D15) | M12: =IF('REGISTER SK'!E15="","",'REGISTER SK'!E15) | N12: =IF(G12="","",IF(OR(G12="GTT",G12="PTT"),"--",VLOOKUP(F12,'Data Induk Pegawai'!B:AE,4,FALSE))) | O12: Pemalang, 20 Februari 1981 | P12: =IF(G12="","",VLOOKUP(F12,'Data Induk Pegawai'!B:AE,7,FALSE)) | R12: =IF(G12="","","Nomor "&RIGHT(VLOOKUP(F12,'Data Induk Pegawai'!B:AE,12,FALSE),2)&" Tahun "&MID(VLOOKUP(F12,'Data Induk Pegawai'!B:AE,12,FALSE),5,4)) | S12: =IF(G12="","",VLOOKUP(F12,'Data Induk Pegawai'!B:AE,11,FALSE)) | U12: =IF(Y12="","",IF(Z12<1,AA12&" Bulan",IF(AND(Z12>0,AA12=0),Z12&" Tahun",Z12&" Tahun "&AA12&" Bulan"))) | W12: =V12&H12 | Y12: =IFERROR(IF(S12="","",DATEDIF(S12,M12,"M")),"?") | Z12: =IFERROR(IF(Y12="","",ROUNDDOWN(Y12/12,0)),"-") | AA12: =IFERROR(IF(Y12="","",Y12-Z12*12),"-") | AB12: =COUNTIFS(AC12:AC$596,AC12)&AC12 -> 585 | AC12: =IF(LEFT(V12,16)="SK Pemberhentian","OUT"&F12,IF(RIGHT(G12,2)="TT","GPTT",IF(RIGHT(G12,2)="TY","GPTY",G12))&F12) | AD12: =COUNTIFS(AC$2:AC12,AC12)&AC12 -> 11 | AE12: =IF(LEFT(V12,16)="SK Pemberhentian",E12&"OUT"&F12,E12&G12&F12) | AF12: =G12&"."&D12&"."&I12 -> .. | AG12: =L12 | AH12: =M12 | AI12: =IF(AG12="","",AJ12&" "&VLOOKUP(AK12,AX:AY,2,FALSE)&" "&AL12) | AJ12: =TEXT(AG12,"D") | AK12: =TEXT(AG12,"MMMM") | AL12: =TEXT(AG12,"YYYY") | AM12: =IF(AI12="","",AN12&" "&VLOOKUP(AO12,AX:AY,2,FALSE)&" "&AP12) | AN12: =TEXT(S12,"D") | AO12: =TEXT(S12,"MMMM") | AP12: =TEXT(S12,"YYYY") | AQ12: =IF(AM12="","",AR12&" "&VLOOKUP(AS12,AX:AY,2,FALSE)&" "&AT12) | AR12: =TEXT(M12,"D") | AS12: =TEXT(M12,"MMMM") | AT12: =TEXT(M12,"YYYY") | AU12: =IF(OR(G12="Umum",G12=""),"",VLOOKUP(VALUE(TEXT(M12,"M")-1),AW:AY,3,FALSE)) | AW12: 11 | AX12: November | AY12: November | BA12: ='REGISTER SK'!F15 -> 0
A13: 12 | B13: ok | C13: =IF(G13="","",IF(G13="Umum",G13,VLOOKUP(F13,'Data Induk Pegawai'!B:AE,4,FALSE))) | D13: =IF('REGISTER SK'!A16="","",IF('REGISTER SK'!B16=0,D12,'REGISTER SK'!B16)) | E13: =IF(D13="","",D13&"/"&D13+1) | H13: =IF(F13="","",VLOOKUP(F13,'Data Induk Pegawai'!B:U,2,FALSE)) | I13: =IF('REGISTER SK'!C16="","",'REGISTER SK'!C16) | L13: =IF('REGISTER SK'!D16="","",'REGISTER SK'!D16) | M13: =IF('REGISTER SK'!E16="","",'REGISTER SK'!E16) | N13: =IF(G13="","",IF(OR(G13="GTT",G13="PTT"),"--",VLOOKUP(F13,'Data Induk Pegawai'!B:AE,4,FALSE))) | O13: Pemalang, 27 Februari 1990 | P13: =IF(G13="","",VLOOKUP(F13,'Data Induk Pegawai'!B:AE,7,FALSE)) | R13: =IF(G13="","","Nomor "&RIGHT(VLOOKUP(F13,'Data Induk Pegawai'!B:AE,12,FALSE),2)&" Tahun "&MID(VLOOKUP(F13,'Data Induk Pegawai'!B:AE,12,FALSE),5,4)) | S13: =IF(G13="","",VLOOKUP(F13,'Data Induk Pegawai'!B:AE,11,FALSE)) | U13: =IF(Y13="","",IF(Z13<1,AA13&" Bulan",IF(AND(Z13>0,AA13=0),Z13&" Tahun",Z13&" Tahun "&AA13&" Bulan"))) | W13: =V13&H13 | Y13: =IFERROR(IF(S13="","",DATEDIF(S13,M13,"M")),"?") | Z13: =IFERROR(IF(Y13="","",ROUNDDOWN(Y13/12,0)),"-") | AA13: =IFERROR(IF(Y13="","",Y13-Z13*12),"-") | AB13: =COUNTIFS(AC13:AC$596,AC13)&AC13 -> 584 | AC13: =IF(LEFT(V13,16)="SK Pemberhentian","OUT"&F13,IF(RIGHT(G13,2)="TT","GPTT",IF(RIGHT(G13,2)="TY","GPTY",G13))&F13) | AD13: =COUNTIFS(AC$2:AC13,AC13)&AC13 -> 12 | AE13: =IF(LEFT(V13,16)="SK Pemberhentian",E13&"OUT"&F13,E13&G13&F13) | AF13: =G13&"."&D13&"."&I13 -> .. | AG13: =L13 | AH13: =M13 | AI13: =IF(AG13="","",AJ13&" "&VLOOKUP(AK13,AX:AY,2,FALSE)&" "&AL13) | AJ13: =TEXT(AG13,"D") | AK13: =TEXT(AG13,"MMMM") | AL13: =TEXT(AG13,"YYYY") | AM13: =IF(AI13="","",AN13&" "&VLOOKUP(AO13,AX:AY,2,FALSE)&" "&AP13) | AN13: =TEXT(S13,"D") | AO13: =TEXT(S13,"MMMM") | AP13: =TEXT(S13,"YYYY") | AQ13: =IF(AM13="","",AR13&" "&VLOOKUP(AS13,AX:AY,2,FALSE)&" "&AT13) | AR13: =TEXT(M13,"D") | AS13: =TEXT(M13,"MMMM") | AT13: =TEXT(M13,"YYYY") | AU13: =IF(OR(G13="Umum",G13=""),"",VLOOKUP(VALUE(TEXT(M13,"M")-1),AW:AY,3,FALSE)) | AW13: 0 | AX13: December | AY13: Desember | BA13: ='REGISTER SK'!F16 -> 0
A14: 13 | B14: ok | C14: =IF(G14="","",IF(G14="Umum",G14,VLOOKUP(F14,'Data Induk Pegawai'!B:AE,4,FALSE))) | D14: =IF('REGISTER SK'!A17="","",IF('REGISTER SK'!B17=0,D13,'REGISTER SK'!B17)) | E14: =IF(D14="","",D14&"/"&D14+1) | H14: =IF(F14="","",VLOOKUP(F14,'Data Induk Pegawai'!B:U,2,FALSE)) | I14: =IF('REGISTER SK'!C17="","",'REGISTER SK'!C17) | L14: =IF('REGISTER SK'!D17="","",'REGISTER SK'!D17) | M14: =IF('REGISTER SK'!E17="","",'REGISTER SK'!E17) | N14: =IF(G14="","",IF(OR(G14="GTT",G14="PTT"),"--",VLOOKUP(F14,'Data Induk Pegawai'!B:AE,4,FALSE))) | O14: Pemalang, 24 April 1996 | P14: =IF(G14="","",VLOOKUP(F14,'Data Induk Pegawai'!B:AE,7,FALSE)) | R14: =IF(G14="","","Nomor "&RIGHT(VLOOKUP(F14,'Data Induk Pegawai'!B:AE,12,FALSE),2)&" Tahun "&MID(VLOOKUP(F14,'Data Induk Pegawai'!B:AE,12,FALSE),5,4)) | S14: =IF(G14="","",VLOOKUP(F14,'Data Induk Pegawai'!B:AE,11,FALSE)) | U14: =IF(Y14="","",IF(Z14<1,AA14&" Bulan",IF(AND(Z14>0,AA14=0),Z14&" Tahun",Z14&" Tahun "&AA14&" Bulan"))) | W14: =V14&H14 | Y14: =IFERROR(IF(S14="","",DATEDIF(S14,M14,"M")),"?") | Z14: =IFERROR(IF(Y14="","",ROUNDDOWN(Y14/12,0)),"-") | AA14: =IFERROR(IF(Y14="","",Y14-Z14*12),"-") | AB14: =COUNTIFS(AC14:AC$596,AC14)&AC14 -> 583 | AC14: =IF(LEFT(V14,16)="SK Pemberhentian","OUT"&F14,IF(RIGHT(G14,2)="TT","GPTT",IF(RIGHT(G14,2)="TY","GPTY",G14))&F14) | AD14: =COUNTIFS(AC$2:AC14,AC14)&AC14 -> 13 | AE14: =IF(LEFT(V14,16)="SK Pemberhentian",E14&"OUT"&F14,E14&G14&F14) | AF14: =G14&"."&D14&"."&I14 -> .. | AG14: =L14 | AH14: =M14 | AI14: =IF(AG14="","",AJ14&" "&VLOOKUP(AK14,AX:AY,2,FALSE)&" "&AL14) | AJ14: =TEXT(AG14,"D") | AK14: =TEXT(AG14,"MMMM") | AL14: =TEXT(AG14,"YYYY") | AM14: =IF(AI14="","",AN14&" "&VLOOKUP(AO14,AX:AY,2,FALSE)&" "&AP14) | AN14: =TEXT(S14,"D") | AO14: =TEXT(S14,"MMMM") | AP14: =TEXT(S14,"YYYY") | AQ14: =IF(AM14="","",AR14&" "&VLOOKUP(AS14,AX:AY,2,FALSE)&" "&AT14) | AR14: =TEXT(M14,"D") | AS14: =TEXT(M14,"MMMM") | AT14: =TEXT(M14,"YYYY") | AU14: =IF(OR(G14="Umum",G14=""),"",VLOOKUP(VALUE(TEXT(M14,"M")-1),AW:AY,3,FALSE)) | AW14: 1 | AX14: Januari | AY14: Januari | BA14: ='REGISTER SK'!F17 -> 0
A15: 14 | B15: ok | C15: =IF(G15="","",IF(G15="Umum",G15,VLOOKUP(F15,'Data Induk Pegawai'!B:AE,4,FALSE))) | D15: =IF('REGISTER SK'!A18="","",IF('REGISTER SK'!B18=0,D14,'REGISTER SK'!B18)) | E15: =IF(D15="","",D15&"/"&D15+1) | H15: =IF(F15="","",VLOOKUP(F15,'Data Induk Pegawai'!B:U,2,FALSE)) | I15: =IF('REGISTER SK'!C18="","",'REGISTER SK'!C18) | L15: =IF('REGISTER SK'!D18="","",'REGISTER SK'!D18) | M15: =IF('REGISTER SK'!E18="","",'REGISTER SK'!E18) | N15: =IF(G15="","",IF(OR(G15="GTT",G15="PTT"),"--",VLOOKUP(F15,'Data Induk Pegawai'!B:AE,4,FALSE))) | O15: Pemalang, 15 Agustus 1996 | P15: =IF(G15="","",VLOOKUP(F15,'Data Induk Pegawai'!B:AE,7,FALSE)) | R15: =IF(G15="","","Nomor "&RIGHT(VLOOKUP(F15,'Data Induk Pegawai'!B:AE,12,FALSE),2)&" Tahun "&MID(VLOOKUP(F15,'Data Induk Pegawai'!B:AE,12,FALSE),5,4)) | S15: =IF(G15="","",VLOOKUP(F15,'Data Induk Pegawai'!B:AE,11,FALSE)) | U15: =IF(Y15="","",IF(Z15<1,AA15&" Bulan",IF(AND(Z15>0,AA15=0),Z15&" Tahun",Z15&" Tahun "&AA15&" Bulan"))) | W15: =V15&H15 | Y15: =IFERROR(IF(S15="","",DATEDIF(S15,M15,"M")),"?") | Z15: =IFERROR(IF(Y15="","",ROUNDDOWN(Y15/12,0)),"-") | AA15: =IFERROR(IF(Y15="","",Y15-Z15*12),"-") | AB15: =COUNTIFS(AC15:AC$596,AC15)&AC15 -> 582 | AC15: =IF(LEFT(V15,16)="SK Pemberhentian","OUT"&F15,IF(RIGHT(G15,2)="TT","GPTT",IF(RIGHT(G15,2)="TY","GPTY",G15))&F15) | AD15: =COUNTIFS(AC$2:AC15,AC15)&AC15 -> 14 | AE15: =IF(LEFT(V15,16)="SK Pemberhentian",E15&"OUT"&F15,E15&G15&F15) | AF15: =G15&"."&D15&"."&I15 -> .. | AG15: =L15 | AH15: =M15 | AI15: =IF(AG15="","",AJ15&" "&VLOOKUP(AK15,AX:AY,2,FALSE)&" "&AL15) | AJ15: =TEXT(AG15,"D") | AK15: =TEXT(AG15,"MMMM") | AL15: =TEXT(AG15,"YYYY") | AM15: =IF(AI15="","",AN15&" "&VLOOKUP(AO15,AX:AY,2,FALSE)&" "&AP15) | AN15: =TEXT(S15,"D") | AO15: =TEXT(S15,"MMMM") | AP15: =TEXT(S15,"YYYY") | AQ15: =IF(AM15="","",AR15&" "&VLOOKUP(AS15,AX:AY,2,FALSE)&" "&AT15) | AR15: =TEXT(M15,"D") | AS15: =TEXT(M15,"MMMM") | AT15: =TEXT(M15,"YYYY") | AU15: =IF(OR(G15="Umum",G15=""),"",VLOOKUP(VALUE(TEXT(M15,"M")-1),AW:AY,3,FALSE)) | AW15: 2 | AX15: Februari | AY15: Februari | BA15: ='REGISTER SK'!F18 -> 0
A16: 15 | B16: ok | C16: =IF(G16="","",IF(G16="Umum",G16,VLOOKUP(F16,'Data Induk Pegawai'!B:AE,4,FALSE))) | D16: =IF('REGISTER SK'!A19="","",IF('REGISTER SK'!B19=0,D15,'REGISTER SK'!B19)) | E16: =IF(D16="","",D16&"/"&D16+1) | H16: =IF(F16="","",VLOOKUP(F16,'Data Induk Pegawai'!B:U,2,FALSE)) | I16: =IF('REGISTER SK'!C19="","",'REGISTER SK'!C19) | L16: =IF('REGISTER SK'!D19="","",'REGISTER SK'!D19) | M16: =IF('REGISTER SK'!E19="","",'REGISTER SK'!E19) | N16: =IF(G16="","",IF(OR(G16="GTT",G16="PTT"),"--",VLOOKUP(F16,'Data Induk Pegawai'!B:AE,4,FALSE))) | O16: Pemalang, 25 Desember 1986 | P16: =IF(G16="","",VLOOKUP(F16,'Data Induk Pegawai'!B:AE,7,FALSE)) | R16: =IF(G16="","","Nomor "&RIGHT(VLOOKUP(F16,'Data Induk Pegawai'!B:AE,12,FALSE),2)&" Tahun "&MID(VLOOKUP(F16,'Data Induk Pegawai'!B:AE,12,FALSE),5,4)) | S16: =IF(G16="","",VLOOKUP(F16,'Data Induk Pegawai'!B:AE,11,FALSE)) | U16: =IF(Y16="","",IF(Z16<1,AA16&" Bulan",IF(AND(Z16>0,AA16=0),Z16&" Tahun",Z16&" Tahun "&AA16&" Bulan"))) | W16: =V16&H16 | Y16: =IFERROR(IF(S16="","",DATEDIF(S16,M16,"M")),"?") | Z16: =IFERROR(IF(Y16="","",ROUNDDOWN(Y16/12,0)),"-") | AA16: =IFERROR(IF(Y16="","",Y16-Z16*12),"-") | AB16: =COUNTIFS(AC16:AC$596,AC16)&AC16 -> 581 | AC16: =IF(LEFT(V16,16)="SK Pemberhentian","OUT"&F16,IF(RIGHT(G16,2)="TT","GPTT",IF(RIGHT(G16,2)="TY","GPTY",G16))&F16) | AD16: =COUNTIFS(AC$2:AC16,AC16)&AC16 -> 15 | AE16: =IF(LEFT(V16,16)="SK Pemberhentian",E16&"OUT"&F16,E16&G16&F16) | AF16: =G16&"."&D16&"."&I16 -> .. | AG16: =L16 | AH16: =M16 | AI16: =IF(AG16="","",AJ16&" "&VLOOKUP(AK16,AX:AY,2,FALSE)&" "&AL16) | AJ16: =TEXT(AG16,"D") | AK16: =TEXT(AG16,"MMMM") | AL16: =TEXT(AG16,"YYYY") | AM16: =IF(AI16="","",AN16&" "&VLOOKUP(AO16,AX:AY,2,FALSE)&" "&AP16) | AN16: =TEXT(S16,"D") | AO16: =TEXT(S16,"MMMM") | AP16: =TEXT(S16,"YYYY") | AQ16: =IF(AM16="","",AR16&" "&VLOOKUP(AS16,AX:AY,2,FALSE)&" "&AT16) | AR16: =TEXT(M16,"D") | AS16: =TEXT(M16,"MMMM") | AT16: =TEXT(M16,"YYYY") | AU16: =IF(OR(G16="Umum",G16=""),"",VLOOKUP(VALUE(TEXT(M16,"M")-1),AW:AY,3,FALSE)) | AW16: 3 | AX16: Maret | AY16: Maret | BA16: ='REGISTER SK'!F19 -> 0
A17: 16 | B17: ok | C17: =IF(G17="","",IF(G17="Umum",G17,VLOOKUP(F17,'Data Induk Pegawai'!B:AE,4,FALSE))) | D17: =IF('REGISTER SK'!A20="","",IF('REGISTER SK'!B20=0,D16,'REGISTER SK'!B20)) | E17: =IF(D17="","",D17&"/"&D17+1) | H17: =IF(F17="","",VLOOKUP(F17,'Data Induk Pegawai'!B:U,2,FALSE)) | I17: =IF('REGISTER SK'!C20="","",'REGISTER SK'!C20) | L17: =IF('REGISTER SK'!D20="","",'REGISTER SK'!D20) | M17: =IF('REGISTER SK'!E20="","",'REGISTER SK'!E20) | N17: =IF(G17="","",IF(OR(G17="GTT",G17="PTT"),"--",VLOOKUP(F17,'Data Induk Pegawai'!B:AE,4,FALSE))) | O17: Pemalang, 17 Mei 1992 | P17: =IF(G17="","",VLOOKUP(F17,'Data Induk Pegawai'!B:AE,7,FALSE)) | R17: =IF(G17="","","Nomor "&RIGHT(VLOOKUP(F17,'Data Induk Pegawai'!B:AE,12,FALSE),2)&" Tahun "&MID(VLOOKUP(F17,'Data Induk Pegawai'!B:AE,12,FALSE),5,4)) | S17: =IF(G17="","",VLOOKUP(F17,'Data Induk Pegawai'!B:AE,11,FALSE)) | U17: =IF(Y17="","",IF(Z17<1,AA17&" Bulan",IF(AND(Z17>0,AA17=0),Z17&" Tahun",Z17&" Tahun "&AA17&" Bulan"))) | W17: =V17&H17 | Y17: =IFERROR(IF(S17="","",DATEDIF(S17,M17,"M")),"?") | Z17: =IFERROR(IF(Y17="","",ROUNDDOWN(Y17/12,0)),"-") | AA17: =IFERROR(IF(Y17="","",Y17-Z17*12),"-") | AB17: =COUNTIFS(AC17:AC$596,AC17)&AC17 -> 580 | AC17: =IF(LEFT(V17,16)="SK Pemberhentian","OUT"&F17,IF(RIGHT(G17,2)="TT","GPTT",IF(RIGHT(G17,2)="TY","GPTY",G17))&F17) | AD17: =COUNTIFS(AC$2:AC17,AC17)&AC17 -> 16 | AE17: =IF(LEFT(V17,16)="SK Pemberhentian",E17&"OUT"&F17,E17&G17&F17) | AF17: =G17&"."&D17&"."&I17 -> .. | AG17: =L17 | AH17: =M17 | AI17: =IF(AG17="","",AJ17&" "&VLOOKUP(AK17,AX:AY,2,FALSE)&" "&AL17) | AJ17: =TEXT(AG17,"D") | AK17: =TEXT(AG17,"MMMM") | AL17: =TEXT(AG17,"YYYY") | AM17: =IF(AI17="","",AN17&" "&VLOOKUP(AO17,AX:AY,2,FALSE)&" "&AP17) | AN17: =TEXT(S17,"D") | AO17: =TEXT(S17,"MMMM") | AP17: =TEXT(S17,"YYYY") | AQ17: =IF(AM17="","",AR17&" "&VLOOKUP(AS17,AX:AY,2,FALSE)&" "&AT17) | AR17: =TEXT(M17,"D") | AS17: =TEXT(M17,"MMMM") | AT17: =TEXT(M17,"YYYY") | AU17: =IF(OR(G17="Umum",G17=""),"",VLOOKUP(VALUE(TEXT(M17,"M")-1),AW:AY,3,FALSE)) | AW17: 4 | AX17: April | AY17: April | BA17: ='REGISTER SK'!F20 -> 0
A18: 17 | B18: ok | C18: =IF(G18="","",IF(G18="Umum",G18,VLOOKUP(F18,'Data Induk Pegawai'!B:AE,4,FALSE))) | D18: =IF('REGISTER SK'!A21="","",IF('REGISTER SK'!B21=0,D17,'REGISTER SK'!B21)) | E18: =IF(D18="","",D18&"/"&D18+1) | H18: =IF(F18="","",VLOOKUP(F18,'Data Induk Pegawai'!B:U,2,FALSE)) | I18: =IF('REGISTER SK'!C21="","",'REGISTER SK'!C21) | L18: =IF('REGISTER SK'!D21="","",'REGISTER SK'!D21) | M18: =IF('REGISTER SK'!E21="","",'REGISTER SK'!E21) | N18: =IF(G18="","",IF(OR(G18="GTT",G18="PTT"),"--",VLOOKUP(F18,'Data Induk Pegawai'!B:AE,4,FALSE))) | O18: Pemalang, 16 Februari 1997 | P18: =IF(G18="","",VLOOKUP(F18,'Data Induk Pegawai'!B:AE,7,FALSE)) | R18: =IF(G18="","","Nomor "&RIGHT(VLOOKUP(F18,'Data Induk Pegawai'!B:AE,12,FALSE),2)&" Tahun "&MID(VLOOKUP(F18,'Data Induk Pegawai'!B:AE,12,FALSE),5,4)) | S18: =IF(G18="","",VLOOKUP(F18,'Data Induk Pegawai'!B:AE,11,FALSE)) | U18: =IF(Y18="","",IF(Z18<1,AA18&" Bulan",IF(AND(Z18>0,AA18=0),Z18&" Tahun",Z18&" Tahun "&AA18&" Bulan"))) | W18: =V18&H18 | Y18: =IFERROR(IF(S18="","",DATEDIF(S18,M18,"M")),"?") | Z18: =IFERROR(IF(Y18="","",ROUNDDOWN(Y18/12,0)),"-") | AA18: =IFERROR(IF(Y18="","",Y18-Z18*12),"-") | AB18: =COUNTIFS(AC18:AC$596,AC18)&AC18 -> 579 | AC18: =IF(LEFT(V18,16)="SK Pemberhentian","OUT"&F18,IF(RIGHT(G18,2)="TT","GPTT",IF(RIGHT(G18,2)="TY","GPTY",G18))&F18) | AD18: =COUNTIFS(AC$2:AC18,AC18)&AC18 -> 17 | AE18: =IF(LEFT(V18,16)="SK Pemberhentian",E18&"OUT"&F18,E18&G18&F18) | AF18: =G18&"."&D18&"."&I18 -> .. | AG18: =L18 | AH18: =M18 | AI18: =IF(AG18="","",AJ18&" "&VLOOKUP(AK18,AX:AY,2,FALSE)&" "&AL18) | AJ18: =TEXT(AG18,"D") | AK18: =TEXT(AG18,"MMMM") | AL18: =TEXT(AG18,"YYYY") | AM18: =IF(AI18="","",AN18&" "&VLOOKUP(AO18,AX:AY,2,FALSE)&" "&AP18) | AN18: =TEXT(S18,"D") | AO18: =TEXT(S18,"MMMM") | AP18: =TEXT(S18,"YYYY") | AQ18: =IF(AM18="","",AR18&" "&VLOOKUP(AS18,AX:AY,2,FALSE)&" "&AT18) | AR18: =TEXT(M18,"D") | AS18: =TEXT(M18,"MMMM") | AT18: =TEXT(M18,"YYYY") | AU18: =IF(OR(G18="Umum",G18=""),"",VLOOKUP(VALUE(TEXT(M18,"M")-1),AW:AY,3,FALSE)) | AW18: 5 | AX18: Mei | AY18: Mei | BA18: ='REGISTER SK'!F21 -> 0
A19: 18 | B19: ok | C19: =IF(G19="","",IF(G19="Umum",G19,VLOOKUP(F19,'Data Induk Pegawai'!B:AE,4,FALSE))) | D19: =IF('REGISTER SK'!A22="","",IF('REGISTER SK'!B22=0,D18,'REGISTER SK'!B22)) | E19: =IF(D19="","",D19&"/"&D19+1) | H19: =IF(F19="","",VLOOKUP(F19,'Data Induk Pegawai'!B:U,2,FALSE)) | I19: =IF('REGISTER SK'!C22="","",'REGISTER SK'!C22) | L19: =IF('REGISTER SK'!D22="","",'REGISTER SK'!D22) | M19: =IF('REGISTER SK'!E22="","",'REGISTER SK'!E22) | N19: =IF(G19="","",IF(OR(G19="GTT",G19="PTT"),"--",VLOOKUP(F19,'Data Induk Pegawai'!B:AE,4,FALSE))) | O19: Pemalang, 7 Mei 1967 | P19: =IF(G19="","",VLOOKUP(F19,'Data Induk Pegawai'!B:AE,7,FALSE)) | R19: =IF(G19="","","Nomor "&RIGHT(VLOOKUP(F19,'Data Induk Pegawai'!B:AE,12,FALSE),2)&" Tahun "&MID(VLOOKUP(F19,'Data Induk Pegawai'!B:AE,12,FALSE),5,4)) | S19: =IF(G19="","",VLOOKUP(F19,'Data Induk Pegawai'!B:AE,11,FALSE)) | U19: =IF(Y19="","",IF(Z19<1,AA19&" Bulan",IF(AND(Z19>0,AA19=0),Z19&" Tahun",Z19&" Tahun "&AA19&" Bulan"))) | W19: =V19&H19 | Y19: =IFERROR(IF(S19="","",DATEDIF(S19,M19,"M")),"?") | Z19: =IFERROR(IF(Y19="","",ROUNDDOWN(Y19/12,0)),"-") | AA19: =IFERROR(IF(Y19="","",Y19-Z19*12),"-") | AB19: =COUNTIFS(AC19:AC$596,AC19)&AC19 -> 578 | AC19: =IF(LEFT(V19,16)="SK Pemberhentian","OUT"&F19,IF(RIGHT(G19,2)="TT","GPTT",IF(RIGHT(G19,2)="TY","GPTY",G19))&F19) | AD19: =COUNTIFS(AC$2:AC19,AC19)&AC19 -> 18 | AE19: =IF(LEFT(V19,16)="SK Pemberhentian",E19&"OUT"&F19,E19&G19&F19) | AF19: =G19&"."&D19&"."&I19 -> .. | AG19: =L19 | AH19: =M19 | AI19: =IF(AG19="","",AJ19&" "&VLOOKUP(AK19,AX:AY,2,FALSE)&" "&AL19) | AJ19: =TEXT(AG19,"D") | AK19: =TEXT(AG19,"MMMM") | AL19: =TEXT(AG19,"YYYY") | AM19: =IF(AI19="","",AN19&" "&VLOOKUP(AO19,AX:AY,2,FALSE)&" "&AP19) | AN19: =TEXT(S19,"D") | AO19: =TEXT(S19,"MMMM") | AP19: =TEXT(S19,"YYYY") | AQ19: =IF(AM19="","",AR19&" "&VLOOKUP(AS19,AX:AY,2,FALSE)&" "&AT19) | AR19: =TEXT(M19,"D") | AS19: =TEXT(M19,"MMMM") | AT19: =TEXT(M19,"YYYY") | AU19: =IF(OR(G19="Umum",G19=""),"",VLOOKUP(VALUE(TEXT(M19,"M")-1),AW:AY,3,FALSE)) | AW19: 6 | AX19: Juni | AY19: Juni | BA19: ='REGISTER SK'!F22 -> 0
A20: 19 | B20: ok | C20: =IF(G20="","",IF(G20="Umum",G20,VLOOKUP(F20,'Data Induk Pegawai'!B:AE,4,FALSE))) | D20: =IF('REGISTER SK'!A23="","",IF('REGISTER SK'!B23=0,D19,'REGISTER SK'!B23)) | E20: =IF(D20="","",D20&"/"&D20+1) | H20: =IF(F20="","",VLOOKUP(F20,'Data Induk Pegawai'!B:U,2,FALSE)) | I20: =IF('REGISTER SK'!C23="","",'REGISTER SK'!C23) | L20: =IF('REGISTER SK'!D23="","",'REGISTER SK'!D23) | M20: =IF('REGISTER SK'!E23="","",'REGISTER SK'!E23) | N20: =IF(G20="","",IF(OR(G20="GTT",G20="PTT"),"--",VLOOKUP(F20,'Data Induk Pegawai'!B:AE,4,FALSE))) | O20: #N/A | P20: =IF(G20="","",VLOOKUP(F20,'Data Induk Pegawai'!B:AE,7,FALSE)) | R20: =IF(G20="","","Nomor "&RIGHT(VLOOKUP(F20,'Data Induk Pegawai'!B:AE,12,FALSE),2)&" Tahun "&MID(VLOOKUP(F20,'Data Induk Pegawai'!B:AE,12,FALSE),5,4)) | S20: =IF(G20="","",VLOOKUP(F20,'Data Induk Pegawai'!B:AE,11,FALSE)) | U20: =IF(Y20="","",IF(Z20<1,AA20&" Bulan",IF(AND(Z20>0,AA20=0),Z20&" Tahun",Z20&" Tahun "&AA20&" Bulan"))) | W20: =V20&H20 | Y20: =IFERROR(IF(S20="","",DATEDIF(S20,M20,"M")),"?") | Z20: =IFERROR(IF(Y20="","",ROUNDDOWN(Y20/12,0)),"-") | AA20: =IFERROR(IF(Y20="","",Y20-Z20*12),"-") | AB20: =COUNTIFS(AC20:AC$596,AC20)&AC20 -> 577 | AC20: =IF(LEFT(V20,16)="SK Pemberhentian","OUT"&F20,IF(RIGHT(G20,2)="TT","GPTT",IF(RIGHT(G20,2)="TY","GPTY",G20))&F20) | AD20: =COUNTIFS(AC$2:AC20,AC20)&AC20 -> 19 | AE20: =IF(LEFT(V20,16)="SK Pemberhentian",E20&"OUT"&F20,E20&G20&F20) | AF20: =G20&"."&D20&"."&I20 -> .. | AG20: =L20 | AH20: =M20 | AI20: =IF(AG20="","",AJ20&" "&VLOOKUP(AK20,AX:AY,2,FALSE)&" "&AL20) | AJ20: =TEXT(AG20,"D") | AK20: =TEXT(AG20,"MMMM") | AL20: =TEXT(AG20,"YYYY") | AM20: =IF(AI20="","",AN20&" "&VLOOKUP(AO20,AX:AY,2,FALSE)&" "&AP20) | AN20: =TEXT(S20,"D") | AO20: =TEXT(S20,"MMMM") | AP20: =TEXT(S20,"YYYY") | AQ20: =IF(AM20="","",AR20&" "&VLOOKUP(AS20,AX:AY,2,FALSE)&" "&AT20) | AR20: =TEXT(M20,"D") | AS20: =TEXT(M20,"MMMM") | AT20: =TEXT(M20,"YYYY") | AU20: =IF(OR(G20="Umum",G20=""),"",VLOOKUP(VALUE(TEXT(M20,"M")-1),AW:AY,3,FALSE)) | AW20: 7 | AX20: Juli | AY20: Juli | BA20: ='REGISTER SK'!F23 -> 0
A21: 20 | C21: =IF(G21="","",IF(G21="Umum",G21,VLOOKUP(F21,'Data Induk Pegawai'!B:AE,4,FALSE))) | D21: =IF('REGISTER SK'!A24="","",IF('REGISTER SK'!B24=0,D20,'REGISTER SK'!B24)) | E21: =IF(D21="","",D21&"/"&D21+1) | H21: =IF(F21="","",VLOOKUP(F21,'Data Induk Pegawai'!B:U,2,FALSE)) | I21: =IF('REGISTER SK'!C24="","",'REGISTER SK'!C24) | L21: =IF('REGISTER SK'!D24="","",'REGISTER SK'!D24) | M21: =IF('REGISTER SK'!E24="","",'REGISTER SK'!E24) | N21: =IF(G21="","",IF(OR(G21="GTT",G21="PTT"),"--",VLOOKUP(F21,'Data Induk Pegawai'!B:AE,4,FALSE))) | P21: =IF(G21="","",VLOOKUP(F21,'Data Induk Pegawai'!B:AE,7,FALSE)) | R21: =IF(G21="","","Nomor "&RIGHT(VLOOKUP(F21,'Data Induk Pegawai'!B:AE,12,FALSE),2)&" Tahun "&MID(VLOOKUP(F21,'Data Induk Pegawai'!B:AE,12,FALSE),5,4)) | S21: =IF(G21="","",VLOOKUP(F21,'Data Induk Pegawai'!B:AE,11,FALSE)) | U21: =IF(Y21="","",IF(Z21<1,AA21&" Bulan",IF(AND(Z21>0,AA21=0),Z21&" Tahun",Z21&" Tahun "&AA21&" Bulan"))) | W21: =V21&H21 | Y21: =IFERROR(IF(S21="","",DATEDIF(S21,M21,"M")),"?") | Z21: =IFERROR(IF(Y21="","",ROUNDDOWN(Y21/12,0)),"-") | AA21: =IFERROR(IF(Y21="","",Y21-Z21*12),"-") | AB21: =COUNTIFS(AC21:AC$596,AC21)&AC21 -> 576 | AC21: =IF(LEFT(V21,16)="SK Pemberhentian","OUT"&F21,IF(RIGHT(G21,2)="TT","GPTT",IF(RIGHT(G21,2)="TY","GPTY",G21))&F21) | AD21: =COUNTIFS(AC$2:AC21,AC21)&AC21 -> 20 | AE21: =IF(LEFT(V21,16)="SK Pemberhentian",E21&"OUT"&F21,E21&G21&F21) | AF21: =G21&"."&D21&"."&I21 -> .. | AG21: =L21 | AH21: =M21 | AI21: =IF(AG21="","",AJ21&" "&VLOOKUP(AK21,AX:AY,2,FALSE)&" "&AL21) | AJ21: =TEXT(AG21,"D") | AK21: =TEXT(AG21,"MMMM") | AL21: =TEXT(AG21,"YYYY") | AM21: =IF(AI21="","",AN21&" "&VLOOKUP(AO21,AX:AY,2,FALSE)&" "&AP21) | AN21: =TEXT(S21,"D") | AO21: =TEXT(S21,"MMMM") | AP21: =TEXT(S21,"YYYY") | AQ21: =IF(AM21="","",AR21&" "&VLOOKUP(AS21,AX:AY,2,FALSE)&" "&AT21) | AR21: =TEXT(M21,"D") | AS21: =TEXT(M21,"MMMM") | AT21: =TEXT(M21,"YYYY") | AU21: =IF(OR(G21="Umum",G21=""),"",VLOOKUP(VALUE(TEXT(M21,"M")-1),AW:AY,3,FALSE)) | AW21: 8 | AX21: Agustus | AY21: Agustus | BA21: ='REGISTER SK'!F24 -> 0
A22: 21 | B22: ok | C22: =IF(G22="","",IF(G22="Umum",G22,VLOOKUP(F22,'Data Induk Pegawai'!B:AE,4,FALSE))) | D22: =IF('REGISTER SK'!A25="","",IF('REGISTER SK'!B25=0,D21,'REGISTER SK'!B25)) | E22: =IF(D22="","",D22&"/"&D22+1) | H22: =IF(F22="","",VLOOKUP(F22,'Data Induk Pegawai'!B:U,2,FALSE)) | I22: =IF('REGISTER SK'!C25="","",'REGISTER SK'!C25) | L22: =IF('REGISTER SK'!D25="","",'REGISTER SK'!D25) | M22: =IF('REGISTER SK'!E25="","",'REGISTER SK'!E25) | N22: =IF(G22="","",IF(OR(G22="GTT",G22="PTT"),"--",VLOOKUP(F22,'Data Induk Pegawai'!B:AE,4,FALSE))) | O22: Majalengka, 11 Mei 1994 | P22: =IF(G22="","",VLOOKUP(F22,'Data Induk Pegawai'!B:AE,7,FALSE)) | R22: =IF(G22="","","Nomor "&RIGHT(VLOOKUP(F22,'Data Induk Pegawai'!B:AE,12,FALSE),2)&" Tahun "&MID(VLOOKUP(F22,'Data Induk Pegawai'!B:AE,12,FALSE),5,4)) | S22: =IF(G22="","",VLOOKUP(F22,'Data Induk Pegawai'!B:AE,11,FALSE)) | U22: =IF(Y22="","",IF(Z22<1,AA22&" Bulan",IF(AND(Z22>0,AA22=0),Z22&" Tahun",Z22&" Tahun "&AA22&" Bulan"))) | W22: =V22&H22 | Y22: =IFERROR(IF(S22="","",DATEDIF(S22,M22,"M")),"?") | Z22: =IFERROR(IF(Y22="","",ROUNDDOWN(Y22/12,0)),"-") | AA22: =IFERROR(IF(Y22="","",Y22-Z22*12),"-") | AB22: =COUNTIFS(AC22:AC$596,AC22)&AC22 -> 575 | AC22: =IF(LEFT(V22,16)="SK Pemberhentian","OUT"&F22,IF(RIGHT(G22,2)="TT","GPTT",IF(RIGHT(G22,2)="TY","GPTY",G22))&F22) | AD22: =COUNTIFS(AC$2:AC22,AC22)&AC22 -> 21 | AE22: =IF(LEFT(V22,16)="SK Pemberhentian",E22&"OUT"&F22,E22&G22&F22) | AF22: =G22&"."&D22&"."&I22 -> .. | AG22: =L22 | AH22: =M22 | AI22: =IF(AG22="","",AJ22&" "&VLOOKUP(AK22,AX:AY,2,FALSE)&" "&AL22) | AJ22: =TEXT(AG22,"D") | AK22: =TEXT(AG22,"MMMM") | AL22: =TEXT(AG22,"YYYY") | AM22: =IF(AI22="","",AN22&" "&VLOOKUP(AO22,AX:AY,2,FALSE)&" "&AP22) | AN22: =TEXT(S22,"D") | AO22: =TEXT(S22,"MMMM") | AP22: =TEXT(S22,"YYYY") | AQ22: =IF(AM22="","",AR22&" "&VLOOKUP(AS22,AX:AY,2,FALSE)&" "&AT22) | AR22: =TEXT(M22,"D") | AS22: =TEXT(M22,"MMMM") | AT22: =TEXT(M22,"YYYY") | AU22: =IF(OR(G22="Umum",G22=""),"",VLOOKUP(VALUE(TEXT(M22,"M")-1),AW:AY,3,FALSE)) | AW22: 9 | AX22: September | AY22: September | BA22: ='REGISTER SK'!F25 -> 0
A23: 22 | B23: ok | C23: =IF(G23="","",IF(G23="Umum",G23,VLOOKUP(F23,'Data Induk Pegawai'!B:AE,4,FALSE))) | D23: =IF('REGISTER SK'!A26="","",IF('REGISTER SK'!B26=0,D22,'REGISTER SK'!B26)) | E23: =IF(D23="","",D23&"/"&D23+1) | H23: =IF(F23="","",VLOOKUP(F23,'Data Induk Pegawai'!B:U,2,FALSE)) | I23: =IF('REGISTER SK'!C26="","",'REGISTER SK'!C26) | L23: =IF('REGISTER SK'!D26="","",'REGISTER SK'!D26) | M23: =IF('REGISTER SK'!E26="","",'REGISTER SK'!E26) | N23: =IF(G23="","",IF(OR(G23="GTT",G23="PTT"),"--",VLOOKUP(F23,'Data Induk Pegawai'!B:AE,4,FALSE))) | O23: Pemalang, 29 April 1992 | P23: =IF(G23="","",VLOOKUP(F23,'Data Induk Pegawai'!B:AE,7,FALSE)) | R23: =IF(G23="","","Nomor "&RIGHT(VLOOKUP(F23,'Data Induk Pegawai'!B:AE,12,FALSE),2)&" Tahun "&MID(VLOOKUP(F23,'Data Induk Pegawai'!B:AE,12,FALSE),5,4)) | S23: =IF(G23="","",VLOOKUP(F23,'Data Induk Pegawai'!B:AE,11,FALSE)) | U23: =IF(Y23="","",IF(Z23<1,AA23&" Bulan",IF(AND(Z23>0,AA23=0),Z23&" Tahun",Z23&" Tahun "&AA23&" Bulan"))) | W23: =V23&H23 | Y23: =IFERROR(IF(S23="","",DATEDIF(S23,M23,"M")),"?") | Z23: =IFERROR(IF(Y23="","",ROUNDDOWN(Y23/12,0)),"-") | AA23: =IFERROR(IF(Y23="","",Y23-Z23*12),"-") | AB23: =COUNTIFS(AC23:AC$596,AC23)&AC23 -> 574 | AC23: =IF(LEFT(V23,16)="SK Pemberhentian","OUT"&F23,IF(RIGHT(G23,2)="TT","GPTT",IF(RIGHT(G23,2)="TY","GPTY",G23))&F23) | AD23: =COUNTIFS(AC$2:AC23,AC23)&AC23 -> 22 | AE23: =IF(LEFT(V23,16)="SK Pemberhentian",E23&"OUT"&F23,E23&G23&F23) | AF23: =G23&"."&D23&"."&I23 -> .. | AG23: =L23 | AH23: =M23 | AI23: =IF(AG23="","",AJ23&" "&VLOOKUP(AK23,AX:AY,2,FALSE)&" "&AL23) | AJ23: =TEXT(AG23,"D") | AK23: =TEXT(AG23,"MMMM") | AL23: =TEXT(AG23,"YYYY") | AM23: =IF(AI23="","",AN23&" "&VLOOKUP(AO23,AX:AY,2,FALSE)&" "&AP23) | AN23: =TEXT(S23,"D") | AO23: =TEXT(S23,"MMMM") | AP23: =TEXT(S23,"YYYY") | AQ23: =IF(AM23="","",AR23&" "&VLOOKUP(AS23,AX:AY,2,FALSE)&" "&AT23) | AR23: =TEXT(M23,"D") | AS23: =TEXT(M23,"MMMM") | AT23: =TEXT(M23,"YYYY") | AU23: =IF(OR(G23="Umum",G23=""),"",VLOOKUP(VALUE(TEXT(M23,"M")-1),AW:AY,3,FALSE)) | AW23: 10 | AX23: Oktober | AY23: Oktober | BA23: ='REGISTER SK'!F26 -> 0
A24: 23 | B24: ok | C24: =IF(G24="","",IF(G24="Umum",G24,VLOOKUP(F24,'Data Induk Pegawai'!B:AE,4,FALSE))) | D24: =IF('REGISTER SK'!A27="","",IF('REGISTER SK'!B27=0,D23,'REGISTER SK'!B27)) | E24: =IF(D24="","",D24&"/"&D24+1) | H24: =IF(F24="","",VLOOKUP(F24,'Data Induk Pegawai'!B:U,2,FALSE)) | I24: =IF('REGISTER SK'!C27="","",'REGISTER SK'!C27) | L24: =IF('REGISTER SK'!D27="","",'REGISTER SK'!D27) | M24: =IF('REGISTER SK'!E27="","",'REGISTER SK'!E27) | N24: =IF(G24="","",IF(OR(G24="GTT",G24="PTT"),"--",VLOOKUP(F24,'Data Induk Pegawai'!B:AE,4,FALSE))) | O24: Pemalang, 17 Mei 1992 | P24: =IF(G24="","",VLOOKUP(F24,'Data Induk Pegawai'!B:AE,7,FALSE)) | R24: =IF(G24="","","Nomor "&RIGHT(VLOOKUP(F24,'Data Induk Pegawai'!B:AE,12,FALSE),2)&" Tahun "&MID(VLOOKUP(F24,'Data Induk Pegawai'!B:AE,12,FALSE),5,4)) | S24: =IF(G24="","",VLOOKUP(F24,'Data Induk Pegawai'!B:AE,11,FALSE)) | U24: =IF(Y24="","",IF(Z24<1,AA24&" Bulan",IF(AND(Z24>0,AA24=0),Z24&" Tahun",Z24&" Tahun "&AA24&" Bulan"))) | W24: =V24&H24 | Y24: =IFERROR(IF(S24="","",DATEDIF(S24,M24,"M")),"?") | Z24: =IFERROR(IF(Y24="","",ROUNDDOWN(Y24/12,0)),"-") | AA24: =IFERROR(IF(Y24="","",Y24-Z24*12),"-") | AB24: =COUNTIFS(AC24:AC$596,AC24)&AC24 -> 573 | AC24: =IF(LEFT(V24,16)="SK Pemberhentian","OUT"&F24,IF(RIGHT(G24,2)="TT","GPTT",IF(RIGHT(G24,2)="TY","GPTY",G24))&F24) | AD24: =COUNTIFS(AC$2:AC24,AC24)&AC24 -> 23 | AE24: =IF(LEFT(V24,16)="SK Pemberhentian",E24&"OUT"&F24,E24&G24&F24) | AF24: =G24&"."&D24&"."&I24 -> .. | AG24: =L24 | AH24: =M24 | AI24: =IF(AG24="","",AJ24&" "&VLOOKUP(AK24,AX:AY,2,FALSE)&" "&AL24) | AJ24: =TEXT(AG24,"D") | AK24: =TEXT(AG24,"MMMM") | AL24: =TEXT(AG24,"YYYY") | AM24: =IF(AI24="","",AN24&" "&VLOOKUP(AO24,AX:AY,2,FALSE)&" "&AP24) | AN24: =TEXT(S24,"D") | AO24: =TEXT(S24,"MMMM") | AP24: =TEXT(S24,"YYYY") | AQ24: =IF(AM24="","",AR24&" "&VLOOKUP(AS24,AX:AY,2,FALSE)&" "&AT24) | AR24: =TEXT(M24,"D") | AS24: =TEXT(M24,"MMMM") | AT24: =TEXT(M24,"YYYY") | AU24: =IF(OR(G24="Umum",G24=""),"",VLOOKUP(VALUE(TEXT(M24,"M")-1),AW:AY,3,FALSE)) | AW24: 11 | AX24: November | AY24: November | BA24: ='REGISTER SK'!F27 -> 0
A25: 24 | B25: ok | C25: =IF(G25="","",IF(G25="Umum",G25,VLOOKUP(F25,'Data Induk Pegawai'!B:AE,4,FALSE))) | D25: =IF('REGISTER SK'!A28="","",IF('REGISTER SK'!B28=0,D24,'REGISTER SK'!B28)) | E25: =IF(D25="","",D25&"/"&D25+1) | H25: =IF(F25="","",VLOOKUP(F25,'Data Induk Pegawai'!B:U,2,FALSE)) | I25: =IF('REGISTER SK'!C28="","",'REGISTER SK'!C28) | L25: =IF('REGISTER SK'!D28="","",'REGISTER SK'!D28) | M25: =IF('REGISTER SK'!E28="","",'REGISTER SK'!E28) | N25: =IF(G25="","",IF(OR(G25="GTT",G25="PTT"),"--",VLOOKUP(F25,'Data Induk Pegawai'!B:AE,4,FALSE))) | O25: Pemalang, 16 Februari 1997 | P25: =IF(G25="","",VLOOKUP(F25,'Data Induk Pegawai'!B:AE,7,FALSE)) | R25: =IF(G25="","","Nomor "&RIGHT(VLOOKUP(F25,'Data Induk Pegawai'!B:AE,12,FALSE),2)&" Tahun "&MID(VLOOKUP(F25,'Data Induk Pegawai'!B:AE,12,FALSE),5,4)) | S25: =IF(G25="","",VLOOKUP(F25,'Data Induk Pegawai'!B:AE,11,FALSE)) | U25: =IF(Y25="","",IF(Z25<1,AA25&" Bulan",IF(AND(Z25>0,AA25=0),Z25&" Tahun",Z25&" Tahun "&AA25&" Bulan"))) | W25: =V25&H25 | Y25: =IFERROR(IF(S25="","",DATEDIF(S25,M25,"M")),"?") | Z25: =IFERROR(IF(Y25="","",ROUNDDOWN(Y25/12,0)),"-") | AA25: =IFERROR(IF(Y25="","",Y25-Z25*12),"-") | AB25: =COUNTIFS(AC25:AC$596,AC25)&AC25 -> 572 | AC25: =IF(LEFT(V25,16)="SK Pemberhentian","OUT"&F25,IF(RIGHT(G25,2)="TT","GPTT",IF(RIGHT(G25,2)="TY","GPTY",G25))&F25) | AD25: =COUNTIFS(AC$2:AC25,AC25)&AC25 -> 24 | AE25: =IF(LEFT(V25,16)="SK Pemberhentian",E25&"OUT"&F25,E25&G25&F25) | AF25: =G25&"."&D25&"."&I25 -> .. | AG25: =L25 | AH25: =M25 | AI25: =IF(AG25="","",AJ25&" "&VLOOKUP(AK25,AX:AY,2,FALSE)&" "&AL25) | AJ25: =TEXT(AG25,"D") | AK25: =TEXT(AG25,"MMMM") | AL25: =TEXT(AG25,"YYYY") | AM25: =IF(AI25="","",AN25&" "&VLOOKUP(AO25,AX:AY,2,FALSE)&" "&AP25) | AN25: =TEXT(S25,"D") | AO25: =TEXT(S25,"MMMM") | AP25: =TEXT(S25,"YYYY") | AQ25: =IF(AM25="","",AR25&" "&VLOOKUP(AS25,AX:AY,2,FALSE)&" "&AT25) | AR25: =TEXT(M25,"D") | AS25: =TEXT(M25,"MMMM") | AT25: =TEXT(M25,"YYYY") | AU25: =IF(OR(G25="Umum",G25=""),"",VLOOKUP(VALUE(TEXT(M25,"M")-1),AW:AY,3,FALSE)) | AW25: 0 | AX25: Desember | AY25: Desember | BA25: ='REGISTER SK'!F28 -> 0
A26: 25 | B26: ok | C26: =IF(G26="","",IF(G26="Umum",G26,VLOOKUP(F26,'Data Induk Pegawai'!B:AE,4,FALSE))) | D26: =IF('REGISTER SK'!A29="","",IF('REGISTER SK'!B29=0,D25,'REGISTER SK'!B29)) | E26: =IF(D26="","",D26&"/"&D26+1) | H26: =IF(F26="","",VLOOKUP(F26,'Data Induk Pegawai'!B:U,2,FALSE)) | I26: =IF('REGISTER SK'!C29="","",'REGISTER SK'!C29) | L26: =IF('REGISTER SK'!D29="","",'REGISTER SK'!D29) | M26: =IF('REGISTER SK'!E29="","",'REGISTER SK'!E29) | N26: =IF(G26="","",IF(OR(G26="GTT",G26="PTT"),"--",VLOOKUP(F26,'Data Induk Pegawai'!B:AE,4,FALSE))) | O26: Pemalang, 7 Mei 1967 | P26: =IF(G26="","",VLOOKUP(F26,'Data Induk Pegawai'!B:AE,7,FALSE)) | R26: =IF(G26="","","Nomor "&RIGHT(VLOOKUP(F26,'Data Induk Pegawai'!B:AE,12,FALSE),2)&" Tahun "&MID(VLOOKUP(F26,'Data Induk Pegawai'!B:AE,12,FALSE),5,4)) | S26: =IF(G26="","",VLOOKUP(F26,'Data Induk Pegawai'!B:AE,11,FALSE)) | U26: =IF(Y26="","",IF(Z26<1,AA26&" Bulan",IF(AND(Z26>0,AA26=0),Z26&" Tahun",Z26&" Tahun "&AA26&" Bulan"))) | W26: =V26&H26 | Y26: =IFERROR(IF(S26="","",DATEDIF(S26,M26,"M")),"?") | Z26: =IFERROR(IF(Y26="","",ROUNDDOWN(Y26/12,0)),"-") | AA26: =IFERROR(IF(Y26="","",Y26-Z26*12),"-") | AB26: =COUNTIFS(AC26:AC$596,AC26)&AC26 -> 571 | AC26: =IF(LEFT(V26,16)="SK Pemberhentian","OUT"&F26,IF(RIGHT(G26,2)="TT","GPTT",IF(RIGHT(G26,2)="TY","GPTY",G26))&F26) | AD26: =COUNTIFS(AC$2:AC26,AC26)&AC26 -> 25 | AE26: =IF(LEFT(V26,16)="SK Pemberhentian",E26&"OUT"&F26,E26&G26&F26) | AF26: =G26&"."&D26&"."&I26 -> .. | AG26: =L26 | AH26: =M26 | AI26: =IF(AG26="","",AJ26&" "&VLOOKUP(AK26,AX:AY,2,FALSE)&" "&AL26) | AJ26: =TEXT(AG26,"D") | AK26: =TEXT(AG26,"MMMM") | AL26: =TEXT(AG26,"YYYY") | AM26: =IF(AI26="","",AN26&" "&VLOOKUP(AO26,AX:AY,2,FALSE)&" "&AP26) | AN26: =TEXT(S26,"D") | AO26: =TEXT(S26,"MMMM") | AP26: =TEXT(S26,"YYYY") | AQ26: =IF(AM26="","",AR26&" "&VLOOKUP(AS26,AX:AY,2,FALSE)&" "&AT26) | AR26: =TEXT(M26,"D") | AS26: =TEXT(M26,"MMMM") | AT26: =TEXT(M26,"YYYY") | AU26: =IF(OR(G26="Umum",G26=""),"",VLOOKUP(VALUE(TEXT(M26,"M")-1),AW:AY,3,FALSE)) | BA26: ='REGISTER SK'!F29 -> 0
A27: 26 | B27: ok | C27: =IF(G27="","",IF(G27="Umum",G27,VLOOKUP(F27,'Data Induk Pegawai'!B:AE,4,FALSE))) | D27: =IF('REGISTER SK'!A30="","",IF('REGISTER SK'!B30=0,D26,'REGISTER SK'!B30)) | E27: =IF(D27="","",D27&"/"&D27+1) | H27: =IF(F27="","",VLOOKUP(F27,'Data Induk Pegawai'!B:U,2,FALSE)) | I27: =IF('REGISTER SK'!C30="","",'REGISTER SK'!C30) | L27: =IF('REGISTER SK'!D30="","",'REGISTER SK'!D30) | M27: =IF('REGISTER SK'!E30="","",'REGISTER SK'!E30) | N27: =IF(G27="","",IF(OR(G27="GTT",G27="PTT"),"--",VLOOKUP(F27,'Data Induk Pegawai'!B:AE,4,FALSE))) | O27: Tegal, 19 Juni 1984 | P27: =IF(G27="","",VLOOKUP(F27,'Data Induk Pegawai'!B:AE,7,FALSE)) | R27: =IF(G27="","","Nomor "&RIGHT(VLOOKUP(F27,'Data Induk Pegawai'!B:AE,12,FALSE),2)&" Tahun "&MID(VLOOKUP(F27,'Data Induk Pegawai'!B:AE,12,FALSE),5,4)) | S27: =IF(G27="","",VLOOKUP(F27,'Data Induk Pegawai'!B:AE,11,FALSE)) | U27: =IF(Y27="","",IF(Z27<1,AA27&" Bulan",IF(AND(Z27>0,AA27=0),Z27&" Tahun",Z27&" Tahun "&AA27&" Bulan"))) | W27: =V27&H27 | Y27: =IFERROR(IF(S27="","",DATEDIF(S27,M27,"M")),"?") | Z27: =IFERROR(IF(Y27="","",ROUNDDOWN(Y27/12,0)),"-") | AA27: =IFERROR(IF(Y27="","",Y27-Z27*12),"-") | AB27: =COUNTIFS(AC27:AC$596,AC27)&AC27 -> 570 | AC27: =IF(LEFT(V27,16)="SK Pemberhentian","OUT"&F27,IF(RIGHT(G27,2)="TT","GPTT",IF(RIGHT(G27,2)="TY","GPTY",G27))&F27) | AD27: =COUNTIFS(AC$2:AC27,AC27)&AC27 -> 26 | AE27: =IF(LEFT(V27,16)="SK Pemberhentian",E27&"OUT"&F27,E27&G27&F27) | AF27: =G27&"."&D27&"."&I27 -> .. | AG27: =L27 | AH27: =M27 | AI27: =IF(AG27="","",AJ27&" "&VLOOKUP(AK27,AX:AY,2,FALSE)&" "&AL27) | AJ27: =TEXT(AG27,"D") | AK27: =TEXT(AG27,"MMMM") | AL27: =TEXT(AG27,"YYYY") | AM27: =IF(AI27="","",AN27&" "&VLOOKUP(AO27,AX:AY,2,FALSE)&" "&AP27) | AN27: =TEXT(S27,"D") | AO27: =TEXT(S27,"MMMM") | AP27: =TEXT(S27,"YYYY") | AQ27: =IF(AM27="","",AR27&" "&VLOOKUP(AS27,AX:AY,2,FALSE)&" "&AT27) | AR27: =TEXT(M27,"D") | AS27: =TEXT(M27,"MMMM") | AT27: =TEXT(M27,"YYYY") | AU27: =IF(OR(G27="Umum",G27=""),"",VLOOKUP(VALUE(TEXT(M27,"M")-1),AW:AY,3,FALSE)) | BA27: ='REGISTER SK'!F30 -> 0
A28: 27 | B28: ok | C28: =IF(G28="","",IF(G28="Umum",G28,VLOOKUP(F28,'Data Induk Pegawai'!B:AE,4,FALSE))) | D28: =IF('REGISTER SK'!A31="","",IF('REGISTER SK'!B31=0,D27,'REGISTER SK'!B31)) | E28: =IF(D28="","",D28&"/"&D28+1) | H28: =IF(F28="","",VLOOKUP(F28,'Data Induk Pegawai'!B:U,2,FALSE)) | I28: =IF('REGISTER SK'!C31="","",'REGISTER SK'!C31) | L28: =IF('REGISTER SK'!D31="","",'REGISTER SK'!D31) | M28: =IF('REGISTER SK'!E31="","",'REGISTER SK'!E31) | N28: =IF(G28="","",IF(OR(G28="GTT",G28="PTT"),"--",VLOOKUP(F28,'Data Induk Pegawai'!B:AE,4,FALSE))) | O28: Pemalang, 30 September 1993 | P28: =IF(G28="","",VLOOKUP(F28,'Data Induk Pegawai'!B:AE,7,FALSE)) | R28: =IF(G28="","","Nomor "&RIGHT(VLOOKUP(F28,'Data Induk Pegawai'!B:AE,12,FALSE),2)&" Tahun "&MID(VLOOKUP(F28,'Data Induk Pegawai'!B:AE,12,FALSE),5,4)) | S28: =IF(G28="","",VLOOKUP(F28,'Data Induk Pegawai'!B:AE,11,FALSE)) | U28: =IF(Y28="","",IF(Z28<1,AA28&" Bulan",IF(AND(Z28>0,AA28=0),Z28&" Tahun",Z28&" Tahun "&AA28&" Bulan"))) | W28: =V28&H28 | Y28: =IFERROR(IF(S28="","",DATEDIF(S28,M28,"M")),"?") | Z28: =IFERROR(IF(Y28="","",ROUNDDOWN(Y28/12,0)),"-") | AA28: =IFERROR(IF(Y28="","",Y28-Z28*12),"-") | AB28: =COUNTIFS(AC28:AC$596,AC28)&AC28 -> 569 | AC28: =IF(LEFT(V28,16)="SK Pemberhentian","OUT"&F28,IF(RIGHT(G28,2)="TT","GPTT",IF(RIGHT(G28,2)="TY","GPTY",G28))&F28) | AD28: =COUNTIFS(AC$2:AC28,AC28)&AC28 -> 27 | AE28: =IF(LEFT(V28,16)="SK Pemberhentian",E28&"OUT"&F28,E28&G28&F28) | AF28: =G28&"."&D28&"."&I28 -> .. | AG28: =L28 | AH28: =M28 | AI28: =IF(AG28="","",AJ28&" "&VLOOKUP(AK28,AX:AY,2,FALSE)&" "&AL28) | AJ28: =TEXT(AG28,"D") | AK28: =TEXT(AG28,"MMMM") | AL28: =TEXT(AG28,"YYYY") | AM28: =IF(AI28="","",AN28&" "&VLOOKUP(AO28,AX:AY,2,FALSE)&" "&AP28) | AN28: =TEXT(S28,"D") | AO28: =TEXT(S28,"MMMM") | AP28: =TEXT(S28,"YYYY") | AQ28: =IF(AM28="","",AR28&" "&VLOOKUP(AS28,AX:AY,2,FALSE)&" "&AT28) | AR28: =TEXT(M28,"D") | AS28: =TEXT(M28,"MMMM") | AT28: =TEXT(M28,"YYYY") | AU28: =IF(OR(G28="Umum",G28=""),"",VLOOKUP(VALUE(TEXT(M28,"M")-1),AW:AY,3,FALSE)) | BA28: ='REGISTER SK'!F31 -> 0
A29: 28 | B29: ok | C29: =IF(G29="","",IF(G29="Umum",G29,VLOOKUP(F29,'Data Induk Pegawai'!B:AE,4,FALSE))) | D29: =IF('REGISTER SK'!A32="","",IF('REGISTER SK'!B32=0,D28,'REGISTER SK'!B32)) | E29: =IF(D29="","",D29&"/"&D29+1) | H29: =IF(F29="","",VLOOKUP(F29,'Data Induk Pegawai'!B:U,2,FALSE)) | I29: =IF('REGISTER SK'!C32="","",'REGISTER SK'!C32) | L29: =IF('REGISTER SK'!D32="","",'REGISTER SK'!D32) | M29: =IF('REGISTER SK'!E32="","",'REGISTER SK'!E32) | N29: =IF(G29="","",IF(OR(G29="GTT",G29="PTT"),"--",VLOOKUP(F29,'Data Induk Pegawai'!B:AE,4,FALSE))) | O29: Pemalang, 30 September 1993 | P29: =IF(G29="","",VLOOKUP(F29,'Data Induk Pegawai'!B:AE,7,FALSE)) | R29: =IF(G29="","","Nomor "&RIGHT(VLOOKUP(F29,'Data Induk Pegawai'!B:AE,12,FALSE),2)&" Tahun "&MID(VLOOKUP(F29,'Data Induk Pegawai'!B:AE,12,FALSE),5,4)) | S29: =IF(G29="","",VLOOKUP(F29,'Data Induk Pegawai'!B:AE,11,FALSE)) | U29: =IF(Y29="","",IF(Z29<1,AA29&" Bulan",IF(AND(Z29>0,AA29=0),Z29&" Tahun",Z29&" Tahun "&AA29&" Bulan"))) | W29: =V29&H29 | Y29: =IFERROR(IF(S29="","",DATEDIF(S29,M29,"M")),"?") | Z29: =IFERROR(IF(Y29="","",ROUNDDOWN(Y29/12,0)),"-") | AA29: =IFERROR(IF(Y29="","",Y29-Z29*12),"-") | AB29: =COUNTIFS(AC29:AC$596,AC29)&AC29 -> 568 | AC29: =IF(LEFT(V29,16)="SK Pemberhentian","OUT"&F29,IF(RIGHT(G29,2)="TT","GPTT",IF(RIGHT(G29,2)="TY","GPTY",G29))&F29) | AD29: =COUNTIFS(AC$2:AC29,AC29)&AC29 -> 28 | AE29: =IF(LEFT(V29,16)="SK Pemberhentian",E29&"OUT"&F29,E29&G29&F29) | AF29: =G29&"."&D29&"."&I29 -> .. | AG29: =L29 | AH29: =M29 | AI29: =IF(AG29="","",AJ29&" "&VLOOKUP(AK29,AX:AY,2,FALSE)&" "&AL29) | AJ29: =TEXT(AG29,"D") | AK29: =TEXT(AG29,"MMMM") | AL29: =TEXT(AG29,"YYYY") | AM29: =IF(AI29="","",AN29&" "&VLOOKUP(AO29,AX:AY,2,FALSE)&" "&AP29) | AN29: =TEXT(S29,"D") | AO29: =TEXT(S29,"MMMM") | AP29: =TEXT(S29,"YYYY") | AQ29: =IF(AM29="","",AR29&" "&VLOOKUP(AS29,AX:AY,2,FALSE)&" "&AT29) | AR29: =TEXT(M29,"D") | AS29: =TEXT(M29,"MMMM") | AT29: =TEXT(M29,"YYYY") | AU29: =IF(OR(G29="Umum",G29=""),"",VLOOKUP(VALUE(TEXT(M29,"M")-1),AW:AY,3,FALSE)) | BA29: ='REGISTER SK'!F32 -> 0
